Internal Server Error: /
Traceback (most recent call last):
  File "C:\Users\Crn96\Desktop\payglen\senv\lib\site-packages\django\core\handlers\exception.py", line 55, in inner
    response = get_response(request)
  File "C:\Users\Crn96\Desktop\payglen\senv\lib\site-packages\django\core\handlers\base.py", line 197, in _get_response
    response = wrapped_callback(request, *callback_args, **callback_kwargs)
  File "C:\Users\Crn96\Desktop\payglen\myauth\views.py", line 33, in protected_view
    if request.user.is_authenticated():
TypeError: 'bool' object is not callable
"GET /?HTTP_API_KEY=067a81fe17a7894a8e8cff5d766465061&HTTP_API_KEY=cb13b24e92fc03801f7370409f26e370f2732bf682b19426805af4dc98eb7facf6d HTTP/1.1" 500 70672
Internal Server Error: /
Traceback (most recent call last):
  File "C:\Users\Crn96\Desktop\payglen\senv\lib\site-packages\django\core\handlers\exception.py", line 55, in inner
    response = get_response(request)
  File "C:\Users\Crn96\Desktop\payglen\senv\lib\site-packages\django\core\handlers\base.py", line 197, in _get_response
    response = wrapped_callback(request, *callback_args, **callback_kwargs)
  File "C:\Users\Crn96\Desktop\payglen\myauth\views.py", line 33, in protected_view
    if request.user.is_authenticated():
TypeError: 'bool' object is not callable
"GET /?HTTP_API_KEY=067a81fe17a7894a8e8cff5d766465061&HTTP_API_KEY=cb13b24e92fc03801f7370409f26e370f2732bf682b19426805af4dc98eb7facf6d HTTP/1.1" 500 70672
Internal Server Error: /
Traceback (most recent call last):
  File "C:\Users\Crn96\Desktop\payglen\senv\lib\site-packages\django\core\handlers\exception.py", line 55, in inner
    response = get_response(request)
  File "C:\Users\Crn96\Desktop\payglen\senv\lib\site-packages\django\core\handlers\base.py", line 197, in _get_response
    response = wrapped_callback(request, *callback_args, **callback_kwargs)
  File "C:\Users\Crn96\Desktop\payglen\myauth\views.py", line 34, in protected_view
    serializer =  APIKeySerializer(request.user.apikey)
  File "C:\Users\Crn96\Desktop\payglen\senv\lib\site-packages\django\utils\functional.py", line 268, in inner
    return func(_wrapped, *args)
AttributeError: 'AnonymousUser' object has no attribute 'apikey'
"GET /?HTTP_API_KEY=067a81fe17a7894a8e8cff5d766465061&HTTP_API_KEY=cb13b24e92fc03801f7370409f26e370f2732bf682b19426805af4dc98eb7facf6d HTTP/1.1" 500 74822
Internal Server Error: /
Traceback (most recent call last):
  File "C:\Users\Crn96\Desktop\payglen\senv\lib\site-packages\django\core\handlers\exception.py", line 55, in inner
    response = get_response(request)
  File "C:\Users\Crn96\Desktop\payglen\senv\lib\site-packages\django\core\handlers\base.py", line 197, in _get_response
    response = wrapped_callback(request, *callback_args, **callback_kwargs)
  File "C:\Users\Crn96\Desktop\payglen\myauth\views.py", line 34, in protected_view
    serializer =  APIKeySerializer(request.user.apikey)
  File "C:\Users\Crn96\Desktop\payglen\senv\lib\site-packages\django\utils\functional.py", line 268, in inner
    return func(_wrapped, *args)
AttributeError: 'AnonymousUser' object has no attribute 'apikey'
"GET /?HTTP_API_KEY=067a81fe17a7894a8e8cff5d766465061&HTTP_API_KEY=cb13b24e92fc03801f7370409f26e370f2732bf682b19426805af4dc98eb7facf6d HTTP/1.1" 500 74822
Internal Server Error: /
Traceback (most recent call last):
  File "C:\Users\Crn96\Desktop\payglen\senv\lib\site-packages\django\core\handlers\exception.py", line 55, in inner
    response = get_response(request)
  File "C:\Users\Crn96\Desktop\payglen\senv\lib\site-packages\django\core\handlers\base.py", line 197, in _get_response
    response = wrapped_callback(request, *callback_args, **callback_kwargs)
  File "C:\Users\Crn96\Desktop\payglen\myauth\views.py", line 34, in protected_view
    serializer =  APIKeySerializer(request.user.apikey)
  File "C:\Users\Crn96\Desktop\payglen\senv\lib\site-packages\django\utils\functional.py", line 268, in inner
    return func(_wrapped, *args)
AttributeError: 'AnonymousUser' object has no attribute 'apikey'
"GET /?HTTP_API_KEY=067a81fe17a7894a8e8cff5d766465061&HTTP_API_KEY=cb13b24e92fc03801f7370409f26e370f2732bf682b19426805af4dc98eb7facf6d HTTP/1.1" 500 74824
Internal Server Error: /api/
Traceback (most recent call last):
  File "C:\Users\Crn96\Desktop\payglen\senv\lib\site-packages\django\core\handlers\exception.py", line 55, in inner
    response = get_response(request)
  File "C:\Users\Crn96\Desktop\payglen\senv\lib\site-packages\django\core\handlers\base.py", line 197, in _get_response
    response = wrapped_callback(request, *callback_args, **callback_kwargs)
  File "C:\Users\Crn96\Desktop\payglen\senv\lib\site-packages\django\views\decorators\csrf.py", line 56, in wrapper_view
    return view_func(*args, **kwargs)
  File "C:\Users\Crn96\Desktop\payglen\senv\lib\site-packages\django\views\generic\base.py", line 104, in view
    return self.dispatch(request, *args, **kwargs)
  File "C:\Users\Crn96\Desktop\payglen\senv\lib\site-packages\rest_framework\views.py", line 509, in dispatch
    response = self.handle_exception(exc)
  File "C:\Users\Crn96\Desktop\payglen\senv\lib\site-packages\rest_framework\views.py", line 469, in handle_exception
    self.raise_uncaught_exception(exc)
  File "C:\Users\Crn96\Desktop\payglen\senv\lib\site-packages\rest_framework\views.py", line 480, in raise_uncaught_exception
    raise exc
  File "C:\Users\Crn96\Desktop\payglen\senv\lib\site-packages\rest_framework\views.py", line 497, in dispatch
    self.initial(request, *args, **kwargs)
  File "C:\Users\Crn96\Desktop\payglen\senv\lib\site-packages\rest_framework\views.py", line 414, in initial
    self.perform_authentication(request)
  File "C:\Users\Crn96\Desktop\payglen\senv\lib\site-packages\rest_framework\views.py", line 324, in perform_authentication
    request.user
  File "C:\Users\Crn96\Desktop\payglen\senv\lib\site-packages\rest_framework\request.py", line 227, in user
    self._authenticate()
  File "C:\Users\Crn96\Desktop\payglen\senv\lib\site-packages\rest_framework\request.py", line 387, in _authenticate
    self.user, self.auth = user_auth_tuple
ValueError: not enough values to unpack (expected 2, got 1)
"GET /api/ HTTP/1.1" 500 110530
Internal Server Error: /api/apikeys/
Traceback (most recent call last):
  File "C:\Users\Crn96\Desktop\payglen\senv\lib\site-packages\django\core\handlers\exception.py", line 55, in inner
    response = get_response(request)
  File "C:\Users\Crn96\Desktop\payglen\senv\lib\site-packages\django\core\handlers\base.py", line 197, in _get_response
    response = wrapped_callback(request, *callback_args, **callback_kwargs)
  File "C:\Users\Crn96\Desktop\payglen\senv\lib\site-packages\django\views\decorators\csrf.py", line 56, in wrapper_view
    return view_func(*args, **kwargs)
  File "C:\Users\Crn96\Desktop\payglen\senv\lib\site-packages\rest_framework\viewsets.py", line 125, in view
    return self.dispatch(request, *args, **kwargs)
  File "C:\Users\Crn96\Desktop\payglen\senv\lib\site-packages\rest_framework\views.py", line 509, in dispatch
    response = self.handle_exception(exc)
  File "C:\Users\Crn96\Desktop\payglen\senv\lib\site-packages\rest_framework\views.py", line 469, in handle_exception
    self.raise_uncaught_exception(exc)
  File "C:\Users\Crn96\Desktop\payglen\senv\lib\site-packages\rest_framework\views.py", line 480, in raise_uncaught_exception
    raise exc
  File "C:\Users\Crn96\Desktop\payglen\senv\lib\site-packages\rest_framework\views.py", line 497, in dispatch
    self.initial(request, *args, **kwargs)
  File "C:\Users\Crn96\Desktop\payglen\senv\lib\site-packages\rest_framework\views.py", line 414, in initial
    self.perform_authentication(request)
  File "C:\Users\Crn96\Desktop\payglen\senv\lib\site-packages\rest_framework\views.py", line 324, in perform_authentication
    request.user
  File "C:\Users\Crn96\Desktop\payglen\senv\lib\site-packages\rest_framework\request.py", line 227, in user
    self._authenticate()
  File "C:\Users\Crn96\Desktop\payglen\senv\lib\site-packages\rest_framework\request.py", line 387, in _authenticate
    self.user, self.auth = user_auth_tuple
ValueError: not enough values to unpack (expected 2, got 1)
"GET /api/apikeys/ HTTP/1.1" 500 111186
Internal Server Error: /api/apikeys/
Traceback (most recent call last):
  File "C:\Users\Crn96\Desktop\payglen\senv\lib\site-packages\django\core\handlers\exception.py", line 55, in inner
    response = get_response(request)
  File "C:\Users\Crn96\Desktop\payglen\senv\lib\site-packages\django\core\handlers\base.py", line 197, in _get_response
    response = wrapped_callback(request, *callback_args, **callback_kwargs)
  File "C:\Users\Crn96\Desktop\payglen\senv\lib\site-packages\django\views\decorators\csrf.py", line 56, in wrapper_view
    return view_func(*args, **kwargs)
  File "C:\Users\Crn96\Desktop\payglen\senv\lib\site-packages\rest_framework\viewsets.py", line 125, in view
    return self.dispatch(request, *args, **kwargs)
  File "C:\Users\Crn96\Desktop\payglen\senv\lib\site-packages\rest_framework\views.py", line 509, in dispatch
    response = self.handle_exception(exc)
  File "C:\Users\Crn96\Desktop\payglen\senv\lib\site-packages\rest_framework\views.py", line 469, in handle_exception
    self.raise_uncaught_exception(exc)
  File "C:\Users\Crn96\Desktop\payglen\senv\lib\site-packages\rest_framework\views.py", line 480, in raise_uncaught_exception
    raise exc
  File "C:\Users\Crn96\Desktop\payglen\senv\lib\site-packages\rest_framework\views.py", line 497, in dispatch
    self.initial(request, *args, **kwargs)
  File "C:\Users\Crn96\Desktop\payglen\senv\lib\site-packages\rest_framework\views.py", line 414, in initial
    self.perform_authentication(request)
  File "C:\Users\Crn96\Desktop\payglen\senv\lib\site-packages\rest_framework\views.py", line 324, in perform_authentication
    request.user
  File "C:\Users\Crn96\Desktop\payglen\senv\lib\site-packages\rest_framework\request.py", line 227, in user
    self._authenticate()
  File "C:\Users\Crn96\Desktop\payglen\senv\lib\site-packages\rest_framework\request.py", line 387, in _authenticate
    self.user, self.auth = user_auth_tuple
ValueError: not enough values to unpack (expected 2, got 1)
"GET /api/apikeys/ HTTP/1.1" 500 111322
Internal Server Error: /api/apikeys/
Traceback (most recent call last):
  File "C:\Users\Crn96\Desktop\payglen\senv\lib\site-packages\django\core\handlers\exception.py", line 55, in inner
    response = get_response(request)
  File "C:\Users\Crn96\Desktop\payglen\senv\lib\site-packages\django\core\handlers\base.py", line 197, in _get_response
    response = wrapped_callback(request, *callback_args, **callback_kwargs)
  File "C:\Users\Crn96\Desktop\payglen\senv\lib\site-packages\django\views\decorators\csrf.py", line 56, in wrapper_view
    return view_func(*args, **kwargs)
  File "C:\Users\Crn96\Desktop\payglen\senv\lib\site-packages\rest_framework\viewsets.py", line 125, in view
    return self.dispatch(request, *args, **kwargs)
  File "C:\Users\Crn96\Desktop\payglen\senv\lib\site-packages\rest_framework\views.py", line 509, in dispatch
    response = self.handle_exception(exc)
  File "C:\Users\Crn96\Desktop\payglen\senv\lib\site-packages\rest_framework\views.py", line 469, in handle_exception
    self.raise_uncaught_exception(exc)
  File "C:\Users\Crn96\Desktop\payglen\senv\lib\site-packages\rest_framework\views.py", line 480, in raise_uncaught_exception
    raise exc
  File "C:\Users\Crn96\Desktop\payglen\senv\lib\site-packages\rest_framework\views.py", line 497, in dispatch
    self.initial(request, *args, **kwargs)
  File "C:\Users\Crn96\Desktop\payglen\senv\lib\site-packages\rest_framework\views.py", line 414, in initial
    self.perform_authentication(request)
  File "C:\Users\Crn96\Desktop\payglen\senv\lib\site-packages\rest_framework\views.py", line 324, in perform_authentication
    request.user
  File "C:\Users\Crn96\Desktop\payglen\senv\lib\site-packages\rest_framework\request.py", line 227, in user
    self._authenticate()
  File "C:\Users\Crn96\Desktop\payglen\senv\lib\site-packages\rest_framework\request.py", line 387, in _authenticate
    self.user, self.auth = user_auth_tuple
ValueError: not enough values to unpack (expected 2, got 1)
"GET /api/apikeys/ HTTP/1.1" 500 111322
Internal Server Error: /api/apikeys/
Traceback (most recent call last):
  File "C:\Users\Crn96\Desktop\payglen\senv\lib\site-packages\django\core\handlers\exception.py", line 55, in inner
    response = get_response(request)
  File "C:\Users\Crn96\Desktop\payglen\senv\lib\site-packages\django\core\handlers\base.py", line 197, in _get_response
    response = wrapped_callback(request, *callback_args, **callback_kwargs)
  File "C:\Users\Crn96\Desktop\payglen\senv\lib\site-packages\django\views\decorators\csrf.py", line 56, in wrapper_view
    return view_func(*args, **kwargs)
  File "C:\Users\Crn96\Desktop\payglen\senv\lib\site-packages\rest_framework\viewsets.py", line 125, in view
    return self.dispatch(request, *args, **kwargs)
  File "C:\Users\Crn96\Desktop\payglen\senv\lib\site-packages\rest_framework\views.py", line 509, in dispatch
    response = self.handle_exception(exc)
  File "C:\Users\Crn96\Desktop\payglen\senv\lib\site-packages\rest_framework\views.py", line 469, in handle_exception
    self.raise_uncaught_exception(exc)
  File "C:\Users\Crn96\Desktop\payglen\senv\lib\site-packages\rest_framework\views.py", line 480, in raise_uncaught_exception
    raise exc
  File "C:\Users\Crn96\Desktop\payglen\senv\lib\site-packages\rest_framework\views.py", line 497, in dispatch
    self.initial(request, *args, **kwargs)
  File "C:\Users\Crn96\Desktop\payglen\senv\lib\site-packages\rest_framework\views.py", line 414, in initial
    self.perform_authentication(request)
  File "C:\Users\Crn96\Desktop\payglen\senv\lib\site-packages\rest_framework\views.py", line 324, in perform_authentication
    request.user
  File "C:\Users\Crn96\Desktop\payglen\senv\lib\site-packages\rest_framework\request.py", line 227, in user
    self._authenticate()
  File "C:\Users\Crn96\Desktop\payglen\senv\lib\site-packages\rest_framework\request.py", line 387, in _authenticate
    self.user, self.auth = user_auth_tuple
ValueError: not enough values to unpack (expected 2, got 1)
"GET /api/apikeys/ HTTP/1.1" 500 111186
Internal Server Error: /api/apikeys/
Traceback (most recent call last):
  File "C:\Users\Crn96\Desktop\payglen\senv\lib\site-packages\django\core\handlers\exception.py", line 55, in inner
    response = get_response(request)
  File "C:\Users\Crn96\Desktop\payglen\senv\lib\site-packages\django\core\handlers\base.py", line 197, in _get_response
    response = wrapped_callback(request, *callback_args, **callback_kwargs)
  File "C:\Users\Crn96\Desktop\payglen\senv\lib\site-packages\django\views\decorators\csrf.py", line 56, in wrapper_view
    return view_func(*args, **kwargs)
  File "C:\Users\Crn96\Desktop\payglen\senv\lib\site-packages\rest_framework\viewsets.py", line 125, in view
    return self.dispatch(request, *args, **kwargs)
  File "C:\Users\Crn96\Desktop\payglen\senv\lib\site-packages\rest_framework\views.py", line 509, in dispatch
    response = self.handle_exception(exc)
  File "C:\Users\Crn96\Desktop\payglen\senv\lib\site-packages\rest_framework\views.py", line 469, in handle_exception
    self.raise_uncaught_exception(exc)
  File "C:\Users\Crn96\Desktop\payglen\senv\lib\site-packages\rest_framework\views.py", line 480, in raise_uncaught_exception
    raise exc
  File "C:\Users\Crn96\Desktop\payglen\senv\lib\site-packages\rest_framework\views.py", line 497, in dispatch
    self.initial(request, *args, **kwargs)
  File "C:\Users\Crn96\Desktop\payglen\senv\lib\site-packages\rest_framework\views.py", line 414, in initial
    self.perform_authentication(request)
  File "C:\Users\Crn96\Desktop\payglen\senv\lib\site-packages\rest_framework\views.py", line 324, in perform_authentication
    request.user
  File "C:\Users\Crn96\Desktop\payglen\senv\lib\site-packages\rest_framework\request.py", line 227, in user
    self._authenticate()
  File "C:\Users\Crn96\Desktop\payglen\senv\lib\site-packages\rest_framework\request.py", line 380, in _authenticate
    user_auth_tuple = authenticator.authenticate(self)
TypeError: authenticate() takes 1 positional argument but 2 were given
"GET /api/apikeys/ HTTP/1.1" 500 111233
Internal Server Error: /
Traceback (most recent call last):
  File "C:\Users\Crn96\Desktop\payglen\senv\lib\site-packages\django\core\handlers\exception.py", line 55, in inner
    response = get_response(request)
  File "C:\Users\Crn96\Desktop\payglen\senv\lib\site-packages\django\core\handlers\base.py", line 197, in _get_response
    response = wrapped_callback(request, *callback_args, **callback_kwargs)
  File "C:\Users\Crn96\Desktop\payglen\myauth\views.py", line 57, in protected_view
    serializer =  APIKeySerializer(request.user.apikey)
  File "C:\Users\Crn96\Desktop\payglen\senv\lib\site-packages\django\utils\functional.py", line 268, in inner
    return func(_wrapped, *args)
AttributeError: 'AnonymousUser' object has no attribute 'apikey'
"GET /?HTTP_API_KEY=067a81fe17a7894a8e8cff5d766465061&HTTP_SECRET_KEY=cb13b24e92fc03801f7370409f26e370f2732bf682b19426805af4dc98eb7facf6d HTTP/1.1" 500 75180
Internal Server Error: /
Traceback (most recent call last):
  File "C:\Users\Crn96\Desktop\payglen\senv\lib\site-packages\django\core\handlers\exception.py", line 55, in inner
    response = get_response(request)
  File "C:\Users\Crn96\Desktop\payglen\senv\lib\site-packages\django\core\handlers\base.py", line 197, in _get_response
    response = wrapped_callback(request, *callback_args, **callback_kwargs)
  File "C:\Users\Crn96\Desktop\payglen\myauth\views.py", line 57, in protected_view
    serializer =  APIKeySerializer(request.user.apikey)
  File "C:\Users\Crn96\Desktop\payglen\senv\lib\site-packages\django\utils\functional.py", line 268, in inner
    return func(_wrapped, *args)
AttributeError: 'AnonymousUser' object has no attribute 'apikey'
"GET /?HTTP_API_KEY=067a81fe17a7894a8e8cff5d766465061&HTTP_SECRET_KEY=cb13b24e92fc03801f7370409f26e370f2732bf682b19426805af4dc98eb7facf6d HTTP/1.1" 500 75180
Internal Server Error: /
Traceback (most recent call last):
  File "C:\Users\Crn96\Desktop\payglen\senv\lib\site-packages\django\core\handlers\exception.py", line 55, in inner
    response = get_response(request)
  File "C:\Users\Crn96\Desktop\payglen\senv\lib\site-packages\django\core\handlers\base.py", line 197, in _get_response
    response = wrapped_callback(request, *callback_args, **callback_kwargs)
  File "C:\Users\Crn96\Desktop\payglen\myauth\views.py", line 58, in protected_view
    serializer =  APIKeySerializer(request.user.apikey)
  File "C:\Users\Crn96\Desktop\payglen\senv\lib\site-packages\django\utils\functional.py", line 268, in inner
    return func(_wrapped, *args)
AttributeError: 'AnonymousUser' object has no attribute 'apikey'
"GET /?HTTP_API_KEY=067a81fe17a7894a8e8cff5d766465061&HTTP_SECRET_KEY=cb13b24e92fc03801f7370409f26e370f2732bf682b19426805af4dc98eb7facf6d HTTP/1.1" 500 75169
Internal Server Error: /
Traceback (most recent call last):
  File "C:\Users\Crn96\Desktop\payglen\senv\lib\site-packages\django\core\handlers\exception.py", line 55, in inner
    response = get_response(request)
  File "C:\Users\Crn96\Desktop\payglen\senv\lib\site-packages\django\core\handlers\base.py", line 197, in _get_response
    response = wrapped_callback(request, *callback_args, **callback_kwargs)
  File "C:\Users\Crn96\Desktop\payglen\myauth\views.py", line 58, in protected_view
    serializer =  APIKeySerializer(request.user.apikey)
  File "C:\Users\Crn96\Desktop\payglen\senv\lib\site-packages\django\utils\functional.py", line 268, in inner
    return func(_wrapped, *args)
AttributeError: 'AnonymousUser' object has no attribute 'apikey'
"GET /?HTTP_API_KEY=067a81fe17a7894a8e8cff5d766465061&HTTP_SECRET_KEY=cb13b24e92fc03801f7370409f26e370f2732bf682b19426805af4dc98eb7facf6d HTTP/1.1" 500 75169
Internal Server Error: /
Traceback (most recent call last):
  File "C:\Users\Crn96\Desktop\payglen\senv\lib\site-packages\django\core\handlers\exception.py", line 55, in inner
    response = get_response(request)
  File "C:\Users\Crn96\Desktop\payglen\senv\lib\site-packages\django\core\handlers\base.py", line 197, in _get_response
    response = wrapped_callback(request, *callback_args, **callback_kwargs)
  File "C:\Users\Crn96\Desktop\payglen\myauth\views.py", line 58, in protected_view
    serializer =  APIKeySerializer(request.user.apikey)
  File "C:\Users\Crn96\Desktop\payglen\senv\lib\site-packages\django\utils\functional.py", line 268, in inner
    return func(_wrapped, *args)
AttributeError: 'AnonymousUser' object has no attribute 'apikey'
"GET /?HTTP_API_KEY=067a81fe17a7894a8e8cff5d766465061&HTTP_SECRET_KEY=cb13b24e92fc03801f7370409f26e370f2732bf682b19426805af4dc98eb7facf6d HTTP/1.1" 500 75169
Internal Server Error: /
Traceback (most recent call last):
  File "C:\Users\Crn96\Desktop\payglen\senv\lib\site-packages\django\core\handlers\exception.py", line 55, in inner
    response = get_response(request)
  File "C:\Users\Crn96\Desktop\payglen\senv\lib\site-packages\django\core\handlers\base.py", line 197, in _get_response
    response = wrapped_callback(request, *callback_args, **callback_kwargs)
  File "C:\Users\Crn96\Desktop\payglen\myauth\views.py", line 58, in protected_view
    serializer =  APIKeySerializer(request.user.apikey)
  File "C:\Users\Crn96\Desktop\payglen\senv\lib\site-packages\django\utils\functional.py", line 268, in inner
    return func(_wrapped, *args)
AttributeError: 'AnonymousUser' object has no attribute 'apikey'
"GET /?HTTP_API_KEY=067a81fe17a7894a8e8cff5d766465061&HTTP_SECRET_KEY=cb13b24e92fc03801f7370409f26e370f2732bf682b19426805af4dc98eb7facf6d HTTP/1.1" 500 75169
Internal Server Error: /
Traceback (most recent call last):
  File "C:\Users\Crn96\Desktop\payglen\senv\lib\site-packages\django\core\handlers\exception.py", line 55, in inner
    response = get_response(request)
  File "C:\Users\Crn96\Desktop\payglen\senv\lib\site-packages\django\core\handlers\base.py", line 197, in _get_response
    response = wrapped_callback(request, *callback_args, **callback_kwargs)
  File "C:\Users\Crn96\Desktop\payglen\myauth\views.py", line 58, in protected_view
    serializer =  APIKeySerializer(request.user.apikey)
  File "C:\Users\Crn96\Desktop\payglen\senv\lib\site-packages\django\utils\functional.py", line 268, in inner
    return func(_wrapped, *args)
AttributeError: 'AnonymousUser' object has no attribute 'apikey'
"GET /?HTTP_API_KEY=067a81fe17a7894a8e8cff5d766465061&HTTP_SECRET_KEY=cb13b24e92fc03801f7370409f26e370f2732bf682b19426805af4dc98eb7facf6d HTTP/1.1" 500 75169
Internal Server Error: /
Traceback (most recent call last):
  File "C:\Users\Crn96\Desktop\payglen\senv\lib\site-packages\django\core\handlers\exception.py", line 55, in inner
    response = get_response(request)
  File "C:\Users\Crn96\Desktop\payglen\senv\lib\site-packages\django\core\handlers\base.py", line 220, in _get_response
    response = response.render()
  File "C:\Users\Crn96\Desktop\payglen\senv\lib\site-packages\django\template\response.py", line 114, in render
    self.content = self.rendered_content
  File "C:\Users\Crn96\Desktop\payglen\senv\lib\site-packages\rest_framework\response.py", line 55, in rendered_content
    assert renderer, ".accepted_renderer not set on Response"
AssertionError: .accepted_renderer not set on Response
"GET /?HTTP_API_KEY=067a81fe17a7894a8e8cff5d766465061&HTTP_SECRET_KEY=cb13b24e92fc03801f7370409f26e370f2732bf682b19426805af4dc98eb7facf6d HTTP/1.1" 500 75370
Internal Server Error: /
Traceback (most recent call last):
  File "C:\Users\Crn96\Desktop\payglen\senv\lib\site-packages\django\core\handlers\exception.py", line 55, in inner
    response = get_response(request)
  File "C:\Users\Crn96\Desktop\payglen\senv\lib\site-packages\django\core\handlers\base.py", line 197, in _get_response
    response = wrapped_callback(request, *callback_args, **callback_kwargs)
  File "C:\Users\Crn96\Desktop\payglen\myauth\views.py", line 58, in protected_view
    serializer =  APIKeySerializer(data=request.data,
AttributeError: 'WSGIRequest' object has no attribute 'data'
"GET / HTTP/1.1" 500 72434
Internal Server Error: /
Traceback (most recent call last):
  File "C:\Users\Crn96\Desktop\payglen\senv\lib\site-packages\django\core\handlers\exception.py", line 55, in inner
    response = get_response(request)
  File "C:\Users\Crn96\Desktop\payglen\senv\lib\site-packages\django\core\handlers\base.py", line 197, in _get_response
    response = wrapped_callback(request, *callback_args, **callback_kwargs)
  File "C:\Users\Crn96\Desktop\payglen\myauth\views.py", line 58, in protected_view
    if request.data:
AttributeError: 'WSGIRequest' object has no attribute 'data'
"GET / HTTP/1.1" 500 72530
Internal Server Error: /
Traceback (most recent call last):
  File "C:\Users\Crn96\Desktop\payglen\senv\lib\site-packages\django\core\handlers\exception.py", line 55, in inner
    response = get_response(request)
  File "C:\Users\Crn96\Desktop\payglen\senv\lib\site-packages\django\core\handlers\base.py", line 197, in _get_response
    response = wrapped_callback(request, *callback_args, **callback_kwargs)
  File "C:\Users\Crn96\Desktop\payglen\myauth\views.py", line 58, in protected_view
    if request.data:
AttributeError: 'WSGIRequest' object has no attribute 'data'
"GET / HTTP/1.1" 500 72530
Internal Server Error: /
Traceback (most recent call last):
  File "C:\Users\Crn96\Desktop\payglen\senv\lib\site-packages\django\core\handlers\exception.py", line 55, in inner
    response = get_response(request)
  File "C:\Users\Crn96\Desktop\payglen\senv\lib\site-packages\django\core\handlers\base.py", line 220, in _get_response
    response = response.render()
  File "C:\Users\Crn96\Desktop\payglen\senv\lib\site-packages\django\template\response.py", line 114, in render
    self.content = self.rendered_content
  File "C:\Users\Crn96\Desktop\payglen\senv\lib\site-packages\rest_framework\response.py", line 55, in rendered_content
    assert renderer, ".accepted_renderer not set on Response"
AssertionError: .accepted_renderer not set on Response
"GET /?HTTP_API_KEY=067a81fe17a7894a8e8cff5d766465061&HTTP_SECRET_KEY=cb13b24e92fc03801f7370409f26e370f2732bf682b19426805af4dc98eb7facf6d HTTP/1.1" 500 75370
Internal Server Error: /
Traceback (most recent call last):
  File "C:\Users\Crn96\Desktop\payglen\senv\lib\site-packages\django\core\handlers\exception.py", line 55, in inner
    response = get_response(request)
  File "C:\Users\Crn96\Desktop\payglen\senv\lib\site-packages\django\core\handlers\base.py", line 197, in _get_response
    response = wrapped_callback(request, *callback_args, **callback_kwargs)
  File "C:\Users\Crn96\Desktop\payglen\myauth\views.py", line 58, in protected_view
    if request.data:
AttributeError: 'WSGIRequest' object has no attribute 'data'
"GET / HTTP/1.1" 500 72530
Internal Server Error: /
Traceback (most recent call last):
  File "C:\Users\Crn96\Desktop\payglen\senv\lib\site-packages\django\core\handlers\exception.py", line 55, in inner
    response = get_response(request)
  File "C:\Users\Crn96\Desktop\payglen\senv\lib\site-packages\django\core\handlers\base.py", line 197, in _get_response
    response = wrapped_callback(request, *callback_args, **callback_kwargs)
  File "C:\Users\Crn96\Desktop\payglen\myauth\views.py", line 58, in protected_view
    if request.data:
AttributeError: 'WSGIRequest' object has no attribute 'data'
"GET / HTTP/1.1" 500 72530
Internal Server Error: /
Traceback (most recent call last):
  File "C:\Users\Crn96\Desktop\payglen\senv\lib\site-packages\django\core\handlers\exception.py", line 55, in inner
    response = get_response(request)
  File "C:\Users\Crn96\Desktop\payglen\senv\lib\site-packages\django\core\handlers\base.py", line 197, in _get_response
    response = wrapped_callback(request, *callback_args, **callback_kwargs)
  File "C:\Users\Crn96\Desktop\payglen\myauth\views.py", line 59, in protected_view
    if request.data:
AttributeError: 'WSGIRequest' object has no attribute 'data'
"GET / HTTP/1.1" 500 72530
Internal Server Error: /
Traceback (most recent call last):
  File "C:\Users\Crn96\Desktop\payglen\senv\lib\site-packages\django\core\handlers\exception.py", line 55, in inner
    response = get_response(request)
  File "C:\Users\Crn96\Desktop\payglen\senv\lib\site-packages\django\core\handlers\base.py", line 204, in _get_response
    self.check_response(response, callback)
  File "C:\Users\Crn96\Desktop\payglen\senv\lib\site-packages\django\core\handlers\base.py", line 332, in check_response
    raise ValueError(
ValueError: The view myauth.views.protected_view didn't return an HttpResponse object. It returned None instead.
"GET /?HTTP_API_KEY=067a81fe17a7894a8e8cff5d766465061&HTTP_SECRET_KEY=cb13b24e92fc03801f7370409f26e370f2732bf682b19426805af4dc98eb7facf6d HTTP/1.1" 500 72094
Internal Server Error: /
Traceback (most recent call last):
  File "C:\Users\Crn96\Desktop\payglen\senv\lib\site-packages\django\core\handlers\exception.py", line 55, in inner
    response = get_response(request)
  File "C:\Users\Crn96\Desktop\payglen\senv\lib\site-packages\django\core\handlers\base.py", line 197, in _get_response
    response = wrapped_callback(request, *callback_args, **callback_kwargs)
  File "C:\Users\Crn96\Desktop\payglen\myauth\views.py", line 59, in protected_view
    if request.data:
AttributeError: 'WSGIRequest' object has no attribute 'data'
"GET / HTTP/1.1" 500 72530
Internal Server Error: /
Traceback (most recent call last):
  File "C:\Users\Crn96\Desktop\payglen\senv\lib\site-packages\django\core\handlers\exception.py", line 55, in inner
    response = get_response(request)
  File "C:\Users\Crn96\Desktop\payglen\senv\lib\site-packages\django\core\handlers\base.py", line 197, in _get_response
    response = wrapped_callback(request, *callback_args, **callback_kwargs)
  File "C:\Users\Crn96\Desktop\payglen\myauth\views.py", line 59, in protected_view
    if request.data:
AttributeError: 'WSGIRequest' object has no attribute 'data'
"GET / HTTP/1.1" 500 72530
Internal Server Error: /
Traceback (most recent call last):
  File "C:\Users\Crn96\Desktop\payglen\senv\lib\site-packages\django\core\handlers\exception.py", line 55, in inner
    response = get_response(request)
  File "C:\Users\Crn96\Desktop\payglen\senv\lib\site-packages\django\core\handlers\base.py", line 220, in _get_response
    response = response.render()
  File "C:\Users\Crn96\Desktop\payglen\senv\lib\site-packages\django\template\response.py", line 114, in render
    self.content = self.rendered_content
  File "C:\Users\Crn96\Desktop\payglen\senv\lib\site-packages\rest_framework\response.py", line 55, in rendered_content
    assert renderer, ".accepted_renderer not set on Response"
AssertionError: .accepted_renderer not set on Response
"GET /?HTTP_API_KEY=067a81fe17a7894a8e8cff5d766465061&HTTP_SECRET_KEY=cb13b24e92fc03801f7370409f26e370f2732bf682b19426805af4dc98eb7facf6d HTTP/1.1" 500 75370
Internal Server Error: /
Traceback (most recent call last):
  File "C:\Users\Crn96\Desktop\payglen\senv\lib\site-packages\django\core\handlers\exception.py", line 55, in inner
    response = get_response(request)
  File "C:\Users\Crn96\Desktop\payglen\senv\lib\site-packages\django\core\handlers\base.py", line 197, in _get_response
    response = wrapped_callback(request, *callback_args, **callback_kwargs)
  File "C:\Users\Crn96\Desktop\payglen\myauth\views.py", line 76, in protected_view
    df = pd.read_html('https://finance.yahoo.com/currencies/')
  File "C:\Users\Crn96\Desktop\payglen\senv\lib\site-packages\pandas\io\html.py", line 1212, in read_html
    return _parse(
  File "C:\Users\Crn96\Desktop\payglen\senv\lib\site-packages\pandas\io\html.py", line 977, in _parse
    parser = _parser_dispatch(flav)
  File "C:\Users\Crn96\Desktop\payglen\senv\lib\site-packages\pandas\io\html.py", line 934, in _parser_dispatch
    raise ImportError("lxml not found, please install it")
ImportError: lxml not found, please install it
"GET / HTTP/1.1" 500 87648
Internal Server Error: /
Traceback (most recent call last):
  File "C:\Users\Crn96\Desktop\payglen\senv\lib\site-packages\django\core\handlers\exception.py", line 55, in inner
    response = get_response(request)
  File "C:\Users\Crn96\Desktop\payglen\senv\lib\site-packages\django\core\handlers\base.py", line 197, in _get_response
    response = wrapped_callback(request, *callback_args, **callback_kwargs)
  File "C:\Users\Crn96\Desktop\payglen\myauth\views.py", line 76, in protected_view
    df = pd.read_html('https://finance.yahoo.com/currencies/')
  File "C:\Users\Crn96\Desktop\payglen\senv\lib\site-packages\pandas\io\html.py", line 1212, in read_html
    return _parse(
  File "C:\Users\Crn96\Desktop\payglen\senv\lib\site-packages\pandas\io\html.py", line 977, in _parse
    parser = _parser_dispatch(flav)
  File "C:\Users\Crn96\Desktop\payglen\senv\lib\site-packages\pandas\io\html.py", line 934, in _parser_dispatch
    raise ImportError("lxml not found, please install it")
ImportError: lxml not found, please install it
"GET / HTTP/1.1" 500 87785
Internal Server Error: /
Traceback (most recent call last):
  File "C:\Users\Crn96\Desktop\payglen\senv\lib\site-packages\django\core\handlers\exception.py", line 55, in inner
    response = get_response(request)
  File "C:\Users\Crn96\Desktop\payglen\senv\lib\site-packages\django\core\handlers\base.py", line 197, in _get_response
    response = wrapped_callback(request, *callback_args, **callback_kwargs)
  File "C:\Users\Crn96\Desktop\payglen\myauth\views.py", line 76, in protected_view
    df = pd.read_html('https://finance.yahoo.com/currencies/')
  File "C:\Users\Crn96\Desktop\payglen\senv\lib\site-packages\pandas\io\html.py", line 1212, in read_html
    return _parse(
  File "C:\Users\Crn96\Desktop\payglen\senv\lib\site-packages\pandas\io\html.py", line 977, in _parse
    parser = _parser_dispatch(flav)
  File "C:\Users\Crn96\Desktop\payglen\senv\lib\site-packages\pandas\io\html.py", line 926, in _parser_dispatch
    raise ImportError("html5lib not found, please install it")
ImportError: html5lib not found, please install it
"GET / HTTP/1.1" 500 88368
Internal Server Error: /
Traceback (most recent call last):
  File "C:\Users\Crn96\Desktop\payglen\senv\lib\site-packages\django\core\handlers\exception.py", line 55, in inner
    response = get_response(request)
  File "C:\Users\Crn96\Desktop\payglen\senv\lib\site-packages\django\core\handlers\base.py", line 197, in _get_response
    response = wrapped_callback(request, *callback_args, **callback_kwargs)
  File "C:\Users\Crn96\Desktop\payglen\myauth\views.py", line 76, in protected_view
    df = pd.read_html('https://finance.yahoo.com/currencies/')
  File "C:\Users\Crn96\Desktop\payglen\senv\lib\site-packages\pandas\io\html.py", line 1212, in read_html
    return _parse(
  File "C:\Users\Crn96\Desktop\payglen\senv\lib\site-packages\pandas\io\html.py", line 977, in _parse
    parser = _parser_dispatch(flav)
  File "C:\Users\Crn96\Desktop\payglen\senv\lib\site-packages\pandas\io\html.py", line 928, in _parser_dispatch
    raise ImportError("BeautifulSoup4 (bs4) not found, please install it")
ImportError: BeautifulSoup4 (bs4) not found, please install it
"GET / HTTP/1.1" 500 88469
Internal Server Error: /
Traceback (most recent call last):
  File "C:\Users\Crn96\Desktop\payglen\senv\lib\site-packages\django\core\handlers\exception.py", line 55, in inner
    response = get_response(request)
  File "C:\Users\Crn96\Desktop\payglen\senv\lib\site-packages\django\core\handlers\base.py", line 197, in _get_response
    response = wrapped_callback(request, *callback_args, **callback_kwargs)
  File "C:\Users\Crn96\Desktop\payglen\myauth\views.py", line 76, in protected_view
    df = pd.read_html('https://finance.yahoo.com/currencies/', flavor='html5lib')
  File "C:\Users\Crn96\Desktop\payglen\senv\lib\site-packages\pandas\io\html.py", line 1212, in read_html
    return _parse(
  File "C:\Users\Crn96\Desktop\payglen\senv\lib\site-packages\pandas\io\html.py", line 977, in _parse
    parser = _parser_dispatch(flav)
  File "C:\Users\Crn96\Desktop\payglen\senv\lib\site-packages\pandas\io\html.py", line 928, in _parser_dispatch
    raise ImportError("BeautifulSoup4 (bs4) not found, please install it")
ImportError: BeautifulSoup4 (bs4) not found, please install it
"GET / HTTP/1.1" 500 88048
Internal Server Error: /
Traceback (most recent call last):
  File "C:\Users\Crn96\Desktop\payglen\senv\lib\site-packages\django\core\handlers\exception.py", line 55, in inner
    response = get_response(request)
  File "C:\Users\Crn96\Desktop\payglen\senv\lib\site-packages\django\core\handlers\base.py", line 197, in _get_response
    response = wrapped_callback(request, *callback_args, **callback_kwargs)
  File "C:\Users\Crn96\Desktop\payglen\myauth\views.py", line 80, in protected_view
    'ZAR_TO_USD': df[22],
IndexError: list index out of range
"GET / HTTP/1.1" 500 74298
Internal Server Error: /
Traceback (most recent call last):
  File "C:\Users\Crn96\Desktop\payglen\senv\lib\site-packages\django\core\handlers\exception.py", line 55, in inner
    response = get_response(request)
  File "C:\Users\Crn96\Desktop\payglen\senv\lib\site-packages\django\core\handlers\base.py", line 197, in _get_response
    response = wrapped_callback(request, *callback_args, **callback_kwargs)
  File "C:\Users\Crn96\Desktop\payglen\myauth\views.py", line 80, in protected_view
    'ZAR_TO_USD': df[22],
IndexError: list index out of range
"GET / HTTP/1.1" 500 74272
Internal Server Error: /
Traceback (most recent call last):
  File "C:\Users\Crn96\Desktop\payglen\senv\lib\site-packages\django\core\handlers\exception.py", line 55, in inner
    response = get_response(request)
  File "C:\Users\Crn96\Desktop\payglen\senv\lib\site-packages\django\core\handlers\base.py", line 197, in _get_response
    response = wrapped_callback(request, *callback_args, **callback_kwargs)
  File "C:\Users\Crn96\Desktop\payglen\myauth\views.py", line 80, in protected_view
    'ZAR_TO_USD': df[22],
IndexError: list index out of range
"GET / HTTP/1.1" 500 74272
Internal Server Error: /
Traceback (most recent call last):
  File "C:\Users\Crn96\Desktop\payglen\senv\lib\site-packages\django\core\handlers\exception.py", line 55, in inner
    response = get_response(request)
  File "C:\Users\Crn96\Desktop\payglen\senv\lib\site-packages\django\core\handlers\base.py", line 220, in _get_response
    response = response.render()
  File "C:\Users\Crn96\Desktop\payglen\senv\lib\site-packages\django\template\response.py", line 114, in render
    self.content = self.rendered_content
  File "C:\Users\Crn96\Desktop\payglen\senv\lib\site-packages\rest_framework\response.py", line 55, in rendered_content
    assert renderer, ".accepted_renderer not set on Response"
AssertionError: .accepted_renderer not set on Response
"GET / HTTP/1.1" 500 76800
Internal Server Error: /
Traceback (most recent call last):
  File "C:\Users\Crn96\Desktop\payglen\senv\lib\site-packages\django\core\handlers\exception.py", line 55, in inner
    response = get_response(request)
  File "C:\Users\Crn96\Desktop\payglen\senv\lib\site-packages\django\core\handlers\base.py", line 197, in _get_response
    response = wrapped_callback(request, *callback_args, **callback_kwargs)
  File "C:\Users\Crn96\Desktop\payglen\myauth\views.py", line 76, in protected_view
    import requests
ModuleNotFoundError: No module named 'requests'
"GET / HTTP/1.1" 500 72621
Internal Server Error: /
Traceback (most recent call last):
  File "C:\Users\Crn96\Desktop\payglen\senv\lib\site-packages\django\core\handlers\exception.py", line 55, in inner
    response = get_response(request)
  File "C:\Users\Crn96\Desktop\payglen\senv\lib\site-packages\django\core\handlers\base.py", line 197, in _get_response
    response = wrapped_callback(request, *callback_args, **callback_kwargs)
  File "C:\Users\Crn96\Desktop\payglen\myauth\views.py", line 81, in protected_view
    print(df[['Name', 'Last Price']])
TypeError: list indices must be integers or slices, not list
"GET / HTTP/1.1" 500 75326
Internal Server Error: /
Traceback (most recent call last):
  File "C:\Users\Crn96\Desktop\payglen\senv\lib\site-packages\pandas\core\indexes\base.py", line 3653, in get_loc
    return self._engine.get_loc(casted_key)
  File "pandas\_libs\index.pyx", line 147, in pandas._libs.index.IndexEngine.get_loc
  File "pandas\_libs\index.pyx", line 176, in pandas._libs.index.IndexEngine.get_loc
  File "pandas\_libs\hashtable_class_helper.pxi", line 7080, in pandas._libs.hashtable.PyObjectHashTable.get_item
  File "pandas\_libs\hashtable_class_helper.pxi", line 7088, in pandas._libs.hashtable.PyObjectHashTable.get_item
KeyError: 22

The above exception was the direct cause of the following exception:

Traceback (most recent call last):
  File "C:\Users\Crn96\Desktop\payglen\senv\lib\site-packages\django\core\handlers\exception.py", line 55, in inner
    response = get_response(request)
  File "C:\Users\Crn96\Desktop\payglen\senv\lib\site-packages\django\core\handlers\base.py", line 197, in _get_response
    response = wrapped_callback(request, *callback_args, **callback_kwargs)
  File "C:\Users\Crn96\Desktop\payglen\myauth\views.py", line 84, in protected_view
    'ZAR_TO_USD': df[0][['Name', 'Last Price']][22],
  File "C:\Users\Crn96\Desktop\payglen\senv\lib\site-packages\pandas\core\frame.py", line 3761, in __getitem__
    indexer = self.columns.get_loc(key)
  File "C:\Users\Crn96\Desktop\payglen\senv\lib\site-packages\pandas\core\indexes\base.py", line 3655, in get_loc
    raise KeyError(key) from err
KeyError: 22
"GET / HTTP/1.1" 500 170608
Internal Server Error: /
Traceback (most recent call last):
  File "C:\Users\Crn96\Desktop\payglen\senv\lib\site-packages\django\core\handlers\exception.py", line 55, in inner
    response = get_response(request)
  File "C:\Users\Crn96\Desktop\payglen\senv\lib\site-packages\django\core\handlers\base.py", line 197, in _get_response
    response = wrapped_callback(request, *callback_args, **callback_kwargs)
  File "C:\Users\Crn96\Desktop\payglen\myauth\views.py", line 83, in protected_view
    return JsonResponse({
  File "C:\Users\Crn96\Desktop\payglen\senv\lib\site-packages\django\http\response.py", line 731, in __init__
    data = json.dumps(data, cls=encoder, **json_dumps_params)
  File "C:\Users\Crn96\AppData\Local\Programs\Python\Python39\lib\json\__init__.py", line 234, in dumps
    return cls(
  File "C:\Users\Crn96\AppData\Local\Programs\Python\Python39\lib\json\encoder.py", line 199, in encode
    chunks = self.iterencode(o, _one_shot=True)
  File "C:\Users\Crn96\AppData\Local\Programs\Python\Python39\lib\json\encoder.py", line 257, in iterencode
    return _iterencode(o, 0)
  File "C:\Users\Crn96\Desktop\payglen\senv\lib\site-packages\django\core\serializers\json.py", line 106, in default
    return super().default(o)
  File "C:\Users\Crn96\AppData\Local\Programs\Python\Python39\lib\json\encoder.py", line 179, in default
    raise TypeError(f'Object of type {o.__class__.__name__} '
TypeError: Object of type DataFrame is not JSON serializable
"GET / HTTP/1.1" 500 105228
Internal Server Error: /
Traceback (most recent call last):
  File "C:\Users\Crn96\Desktop\payglen\senv\lib\site-packages\django\core\handlers\exception.py", line 55, in inner
    response = get_response(request)
  File "C:\Users\Crn96\Desktop\payglen\senv\lib\site-packages\django\core\handlers\base.py", line 197, in _get_response
    response = wrapped_callback(request, *callback_args, **callback_kwargs)
  File "C:\Users\Crn96\Desktop\payglen\myauth\views.py", line 84, in protected_view
    'ZAR_TO_USD': df.to_json(df[0][['Name', 'Last Price']]),
AttributeError: 'list' object has no attribute 'to_json'
"GET / HTTP/1.1" 500 75406
Internal Server Error: /
Traceback (most recent call last):
  File "C:\Users\Crn96\Desktop\payglen\senv\lib\site-packages\django\core\handlers\exception.py", line 55, in inner
    response = get_response(request)
  File "C:\Users\Crn96\Desktop\payglen\senv\lib\site-packages\django\core\handlers\base.py", line 197, in _get_response
    response = wrapped_callback(request, *callback_args, **callback_kwargs)
  File "C:\Users\Crn96\Desktop\payglen\myauth\views.py", line 84, in protected_view
    'ZAR_TO_USD': df.to_json(df[0]),
AttributeError: 'list' object has no attribute 'to_json'
"GET / HTTP/1.1" 500 75318
Internal Server Error: /
Traceback (most recent call last):
  File "C:\Users\Crn96\Desktop\payglen\senv\lib\site-packages\django\core\handlers\exception.py", line 55, in inner
    response = get_response(request)
  File "C:\Users\Crn96\Desktop\payglen\senv\lib\site-packages\django\core\handlers\base.py", line 220, in _get_response
    response = response.render()
  File "C:\Users\Crn96\Desktop\payglen\senv\lib\site-packages\django\template\response.py", line 114, in render
    self.content = self.rendered_content
  File "C:\Users\Crn96\Desktop\payglen\senv\lib\site-packages\rest_framework\response.py", line 55, in rendered_content
    assert renderer, ".accepted_renderer not set on Response"
AssertionError: .accepted_renderer not set on Response
"GET / HTTP/1.1" 500 76800
Internal Server Error: /apiview/
Traceback (most recent call last):
  File "C:\Users\Crn96\Desktop\payglen\senv\lib\site-packages\django\core\handlers\exception.py", line 55, in inner
    response = get_response(request)
  File "C:\Users\Crn96\Desktop\payglen\senv\lib\site-packages\django\core\handlers\base.py", line 197, in _get_response
    response = wrapped_callback(request, *callback_args, **callback_kwargs)
  File "C:\Users\Crn96\Desktop\payglen\senv\lib\site-packages\django\views\decorators\csrf.py", line 56, in wrapper_view
    return view_func(*args, **kwargs)
  File "C:\Users\Crn96\Desktop\payglen\senv\lib\site-packages\django\views\generic\base.py", line 104, in view
    return self.dispatch(request, *args, **kwargs)
  File "C:\Users\Crn96\Desktop\payglen\senv\lib\site-packages\rest_framework\views.py", line 509, in dispatch
    response = self.handle_exception(exc)
  File "C:\Users\Crn96\Desktop\payglen\senv\lib\site-packages\rest_framework\views.py", line 469, in handle_exception
    self.raise_uncaught_exception(exc)
  File "C:\Users\Crn96\Desktop\payglen\senv\lib\site-packages\rest_framework\views.py", line 480, in raise_uncaught_exception
    raise exc
  File "C:\Users\Crn96\Desktop\payglen\senv\lib\site-packages\rest_framework\views.py", line 497, in dispatch
    self.initial(request, *args, **kwargs)
  File "C:\Users\Crn96\Desktop\payglen\senv\lib\site-packages\rest_framework\views.py", line 414, in initial
    self.perform_authentication(request)
  File "C:\Users\Crn96\Desktop\payglen\senv\lib\site-packages\rest_framework\views.py", line 324, in perform_authentication
    request.user
  File "C:\Users\Crn96\Desktop\payglen\senv\lib\site-packages\rest_framework\request.py", line 227, in user
    self._authenticate()
  File "C:\Users\Crn96\Desktop\payglen\senv\lib\site-packages\rest_framework\request.py", line 380, in _authenticate
    user_auth_tuple = authenticator.authenticate(self)
  File "C:\Users\Crn96\Desktop\payglen\senv\lib\site-packages\rest_framework\authentication.py", line 42, in authenticate
    raise NotImplementedError(".authenticate() must be overridden.")
NotImplementedError: .authenticate() must be overridden.
"GET /apiview/ HTTP/1.1" 500 112348
Internal Server Error: /apiview/
Traceback (most recent call last):
  File "C:\Users\Crn96\Desktop\payglen\senv\lib\site-packages\django\core\handlers\exception.py", line 55, in inner
    response = get_response(request)
  File "C:\Users\Crn96\Desktop\payglen\senv\lib\site-packages\django\core\handlers\base.py", line 197, in _get_response
    response = wrapped_callback(request, *callback_args, **callback_kwargs)
  File "C:\Users\Crn96\Desktop\payglen\senv\lib\site-packages\django\views\decorators\csrf.py", line 56, in wrapper_view
    return view_func(*args, **kwargs)
  File "C:\Users\Crn96\Desktop\payglen\senv\lib\site-packages\django\views\generic\base.py", line 104, in view
    return self.dispatch(request, *args, **kwargs)
  File "C:\Users\Crn96\Desktop\payglen\senv\lib\site-packages\rest_framework\views.py", line 509, in dispatch
    response = self.handle_exception(exc)
  File "C:\Users\Crn96\Desktop\payglen\senv\lib\site-packages\rest_framework\views.py", line 469, in handle_exception
    self.raise_uncaught_exception(exc)
  File "C:\Users\Crn96\Desktop\payglen\senv\lib\site-packages\rest_framework\views.py", line 480, in raise_uncaught_exception
    raise exc
  File "C:\Users\Crn96\Desktop\payglen\senv\lib\site-packages\rest_framework\views.py", line 497, in dispatch
    self.initial(request, *args, **kwargs)
  File "C:\Users\Crn96\Desktop\payglen\senv\lib\site-packages\rest_framework\views.py", line 414, in initial
    self.perform_authentication(request)
  File "C:\Users\Crn96\Desktop\payglen\senv\lib\site-packages\rest_framework\views.py", line 324, in perform_authentication
    request.user
  File "C:\Users\Crn96\Desktop\payglen\senv\lib\site-packages\rest_framework\request.py", line 227, in user
    self._authenticate()
  File "C:\Users\Crn96\Desktop\payglen\senv\lib\site-packages\rest_framework\request.py", line 380, in _authenticate
    user_auth_tuple = authenticator.authenticate(self)
  File "C:\Users\Crn96\Desktop\payglen\senv\lib\site-packages\rest_framework\authentication.py", line 42, in authenticate
    raise NotImplementedError(".authenticate() must be overridden.")
NotImplementedError: .authenticate() must be overridden.
"GET /apiview/ HTTP/1.1" 500 112348
Internal Server Error: /apiview/
Traceback (most recent call last):
  File "C:\Users\Crn96\Desktop\payglen\senv\lib\site-packages\django\core\handlers\exception.py", line 55, in inner
    response = get_response(request)
  File "C:\Users\Crn96\Desktop\payglen\senv\lib\site-packages\django\core\handlers\base.py", line 197, in _get_response
    response = wrapped_callback(request, *callback_args, **callback_kwargs)
  File "C:\Users\Crn96\Desktop\payglen\senv\lib\site-packages\django\views\decorators\csrf.py", line 56, in wrapper_view
    return view_func(*args, **kwargs)
  File "C:\Users\Crn96\Desktop\payglen\senv\lib\site-packages\django\views\generic\base.py", line 104, in view
    return self.dispatch(request, *args, **kwargs)
  File "C:\Users\Crn96\Desktop\payglen\senv\lib\site-packages\rest_framework\views.py", line 509, in dispatch
    response = self.handle_exception(exc)
  File "C:\Users\Crn96\Desktop\payglen\senv\lib\site-packages\rest_framework\views.py", line 469, in handle_exception
    self.raise_uncaught_exception(exc)
  File "C:\Users\Crn96\Desktop\payglen\senv\lib\site-packages\rest_framework\views.py", line 480, in raise_uncaught_exception
    raise exc
  File "C:\Users\Crn96\Desktop\payglen\senv\lib\site-packages\rest_framework\views.py", line 506, in dispatch
    response = handler(request, *args, **kwargs)
  File "C:\Users\Crn96\Desktop\payglen\myauth\views.py", line 104, in get
    'api_key': str(request.user.apikey.api_key),
AttributeError: 'AnonymousUser' object has no attribute 'apikey'
"GET /apiview/ HTTP/1.1" 500 98897
Internal Server Error: /login_user
Traceback (most recent call last):
  File "C:\Users\Crn96\Desktop\payglen\senv\lib\site-packages\django\core\handlers\exception.py", line 55, in inner
    response = get_response(request)
  File "C:\Users\Crn96\Desktop\payglen\senv\lib\site-packages\django\core\handlers\base.py", line 197, in _get_response
    response = wrapped_callback(request, *callback_args, **callback_kwargs)
  File "C:\Users\Crn96\Desktop\payglen\senv\lib\site-packages\django\views\decorators\csrf.py", line 56, in wrapper_view
    return view_func(*args, **kwargs)
  File "C:\Users\Crn96\Desktop\payglen\senv\lib\site-packages\django\views\generic\base.py", line 104, in view
    return self.dispatch(request, *args, **kwargs)
  File "C:\Users\Crn96\Desktop\payglen\senv\lib\site-packages\rest_framework\views.py", line 509, in dispatch
    response = self.handle_exception(exc)
  File "C:\Users\Crn96\Desktop\payglen\senv\lib\site-packages\rest_framework\views.py", line 469, in handle_exception
    self.raise_uncaught_exception(exc)
  File "C:\Users\Crn96\Desktop\payglen\senv\lib\site-packages\rest_framework\views.py", line 480, in raise_uncaught_exception
    raise exc
  File "C:\Users\Crn96\Desktop\payglen\senv\lib\site-packages\rest_framework\views.py", line 506, in dispatch
    response = handler(request, *args, **kwargs)
  File "C:\Users\Crn96\Desktop\payglen\senv\lib\site-packages\rest_framework\decorators.py", line 50, in handler
    return func(*args, **kwargs)
  File "C:\Users\Crn96\Desktop\payglen\myauth\views.py", line 92, in login_user_view
    return Response(items)
  File "C:\Users\Crn96\Desktop\payglen\senv\lib\site-packages\rest_framework\response.py", line 38, in __init__
    raise AssertionError(msg)
AssertionError: You passed a Serializer instance as data, but probably meant to pass serialized `.data` or `.error`. representation.
"GET /login_user HTTP/1.1" 500 108032
Internal Server Error: /login_user
Traceback (most recent call last):
  File "C:\Users\Crn96\Desktop\payglen\senv\lib\site-packages\django\core\handlers\exception.py", line 55, in inner
    response = get_response(request)
  File "C:\Users\Crn96\Desktop\payglen\senv\lib\site-packages\django\core\handlers\base.py", line 197, in _get_response
    response = wrapped_callback(request, *callback_args, **callback_kwargs)
  File "C:\Users\Crn96\Desktop\payglen\senv\lib\site-packages\django\views\decorators\csrf.py", line 56, in wrapper_view
    return view_func(*args, **kwargs)
  File "C:\Users\Crn96\Desktop\payglen\senv\lib\site-packages\django\views\generic\base.py", line 104, in view
    return self.dispatch(request, *args, **kwargs)
  File "C:\Users\Crn96\Desktop\payglen\senv\lib\site-packages\rest_framework\views.py", line 509, in dispatch
    response = self.handle_exception(exc)
  File "C:\Users\Crn96\Desktop\payglen\senv\lib\site-packages\rest_framework\views.py", line 469, in handle_exception
    self.raise_uncaught_exception(exc)
  File "C:\Users\Crn96\Desktop\payglen\senv\lib\site-packages\rest_framework\views.py", line 480, in raise_uncaught_exception
    raise exc
  File "C:\Users\Crn96\Desktop\payglen\senv\lib\site-packages\rest_framework\views.py", line 506, in dispatch
    response = handler(request, *args, **kwargs)
  File "C:\Users\Crn96\Desktop\payglen\senv\lib\site-packages\rest_framework\decorators.py", line 50, in handler
    return func(*args, **kwargs)
  File "C:\Users\Crn96\Desktop\payglen\myauth\views.py", line 91, in login_user_view
    a = CustomAPIKeyAuthentication.authenticate(request)
TypeError: authenticate() missing 1 required positional argument: 'request'
"GET /login_user HTTP/1.1" 500 101684
Internal Server Error: /currencies/
Traceback (most recent call last):
  File "C:\Users\Crn96\Desktop\payglen\senv\lib\site-packages\django\core\handlers\exception.py", line 55, in inner
    response = get_response(request)
  File "C:\Users\Crn96\Desktop\payglen\senv\lib\site-packages\django\core\handlers\base.py", line 220, in _get_response
    response = response.render()
  File "C:\Users\Crn96\Desktop\payglen\senv\lib\site-packages\django\template\response.py", line 114, in render
    self.content = self.rendered_content
  File "C:\Users\Crn96\Desktop\payglen\senv\lib\site-packages\rest_framework\response.py", line 70, in rendered_content
    ret = renderer.render(self.data, accepted_media_type, context)
  File "C:\Users\Crn96\Desktop\payglen\senv\lib\site-packages\rest_framework\renderers.py", line 724, in render
    ret = template.render(context, request=renderer_context['request'])
  File "C:\Users\Crn96\Desktop\payglen\senv\lib\site-packages\django\template\backends\django.py", line 61, in render
    return self.template.render(context)
  File "C:\Users\Crn96\Desktop\payglen\senv\lib\site-packages\django\template\base.py", line 175, in render
    return self._render(context)
  File "C:\Users\Crn96\Desktop\payglen\senv\lib\site-packages\django\template\base.py", line 167, in _render
    return self.nodelist.render(context)
  File "C:\Users\Crn96\Desktop\payglen\senv\lib\site-packages\django\template\base.py", line 1005, in render
    return SafeString("".join([node.render_annotated(context) for node in self]))
  File "C:\Users\Crn96\Desktop\payglen\senv\lib\site-packages\django\template\base.py", line 1005, in <listcomp>
    return SafeString("".join([node.render_annotated(context) for node in self]))
  File "C:\Users\Crn96\Desktop\payglen\senv\lib\site-packages\django\template\base.py", line 966, in render_annotated
    return self.render(context)
  File "C:\Users\Crn96\Desktop\payglen\senv\lib\site-packages\django\template\loader_tags.py", line 157, in render
    return compiled_parent._render(context)
  File "C:\Users\Crn96\Desktop\payglen\senv\lib\site-packages\django\template\base.py", line 167, in _render
    return self.nodelist.render(context)
  File "C:\Users\Crn96\Desktop\payglen\senv\lib\site-packages\django\template\base.py", line 1005, in render
    return SafeString("".join([node.render_annotated(context) for node in self]))
  File "C:\Users\Crn96\Desktop\payglen\senv\lib\site-packages\django\template\base.py", line 1005, in <listcomp>
    return SafeString("".join([node.render_annotated(context) for node in self]))
  File "C:\Users\Crn96\Desktop\payglen\senv\lib\site-packages\django\template\base.py", line 966, in render_annotated
    return self.render(context)
  File "C:\Users\Crn96\Desktop\payglen\senv\lib\site-packages\django\template\loader_tags.py", line 63, in render
    result = block.nodelist.render(context)
  File "C:\Users\Crn96\Desktop\payglen\senv\lib\site-packages\django\template\base.py", line 1005, in render
    return SafeString("".join([node.render_annotated(context) for node in self]))
  File "C:\Users\Crn96\Desktop\payglen\senv\lib\site-packages\django\template\base.py", line 1005, in <listcomp>
    return SafeString("".join([node.render_annotated(context) for node in self]))
  File "C:\Users\Crn96\Desktop\payglen\senv\lib\site-packages\django\template\base.py", line 966, in render_annotated
    return self.render(context)
  File "C:\Users\Crn96\Desktop\payglen\senv\lib\site-packages\django\template\loader_tags.py", line 63, in render
    result = block.nodelist.render(context)
  File "C:\Users\Crn96\Desktop\payglen\senv\lib\site-packages\django\template\base.py", line 1005, in render
    return SafeString("".join([node.render_annotated(context) for node in self]))
  File "C:\Users\Crn96\Desktop\payglen\senv\lib\site-packages\django\template\base.py", line 1005, in <listcomp>
    return SafeString("".join([node.render_annotated(context) for node in self]))
  File "C:\Users\Crn96\Desktop\payglen\senv\lib\site-packages\django\template\base.py", line 966, in render_annotated
    return self.render(context)
  File "C:\Users\Crn96\Desktop\payglen\senv\lib\site-packages\django\template\loader_tags.py", line 63, in render
    result = block.nodelist.render(context)
  File "C:\Users\Crn96\Desktop\payglen\senv\lib\site-packages\django\template\base.py", line 1005, in render
    return SafeString("".join([node.render_annotated(context) for node in self]))
  File "C:\Users\Crn96\Desktop\payglen\senv\lib\site-packages\django\template\base.py", line 1005, in <listcomp>
    return SafeString("".join([node.render_annotated(context) for node in self]))
  File "C:\Users\Crn96\Desktop\payglen\senv\lib\site-packages\django\template\base.py", line 966, in render_annotated
    return self.render(context)
  File "C:\Users\Crn96\Desktop\payglen\senv\lib\site-packages\django\template\defaulttags.py", line 471, in render
    url = reverse(view_name, args=args, kwargs=kwargs, current_app=current_app)
  File "C:\Users\Crn96\Desktop\payglen\senv\lib\site-packages\django\urls\base.py", line 88, in reverse
    return resolver._reverse_with_prefix(view, prefix, *args, **kwargs)
  File "C:\Users\Crn96\Desktop\payglen\senv\lib\site-packages\django\urls\resolvers.py", line 828, in _reverse_with_prefix
    raise NoReverseMatch(msg)
django.urls.exceptions.NoReverseMatch: Reverse for 'home' not found. 'home' is not a valid view function or pattern name.
"GET /currencies/ HTTP/1.1" 500 423363
Internal Server Error: /currencies/
Traceback (most recent call last):
  File "C:\Users\Crn96\Desktop\payglen\senv\lib\site-packages\django\core\handlers\exception.py", line 55, in inner
    response = get_response(request)
  File "C:\Users\Crn96\Desktop\payglen\senv\lib\site-packages\django\core\handlers\base.py", line 220, in _get_response
    response = response.render()
  File "C:\Users\Crn96\Desktop\payglen\senv\lib\site-packages\django\template\response.py", line 114, in render
    self.content = self.rendered_content
  File "C:\Users\Crn96\Desktop\payglen\senv\lib\site-packages\rest_framework\response.py", line 70, in rendered_content
    ret = renderer.render(self.data, accepted_media_type, context)
  File "C:\Users\Crn96\Desktop\payglen\senv\lib\site-packages\rest_framework\renderers.py", line 724, in render
    ret = template.render(context, request=renderer_context['request'])
  File "C:\Users\Crn96\Desktop\payglen\senv\lib\site-packages\django\template\backends\django.py", line 61, in render
    return self.template.render(context)
  File "C:\Users\Crn96\Desktop\payglen\senv\lib\site-packages\django\template\base.py", line 175, in render
    return self._render(context)
  File "C:\Users\Crn96\Desktop\payglen\senv\lib\site-packages\django\template\base.py", line 167, in _render
    return self.nodelist.render(context)
  File "C:\Users\Crn96\Desktop\payglen\senv\lib\site-packages\django\template\base.py", line 1005, in render
    return SafeString("".join([node.render_annotated(context) for node in self]))
  File "C:\Users\Crn96\Desktop\payglen\senv\lib\site-packages\django\template\base.py", line 1005, in <listcomp>
    return SafeString("".join([node.render_annotated(context) for node in self]))
  File "C:\Users\Crn96\Desktop\payglen\senv\lib\site-packages\django\template\base.py", line 966, in render_annotated
    return self.render(context)
  File "C:\Users\Crn96\Desktop\payglen\senv\lib\site-packages\django\template\loader_tags.py", line 157, in render
    return compiled_parent._render(context)
  File "C:\Users\Crn96\Desktop\payglen\senv\lib\site-packages\django\template\base.py", line 167, in _render
    return self.nodelist.render(context)
  File "C:\Users\Crn96\Desktop\payglen\senv\lib\site-packages\django\template\base.py", line 1005, in render
    return SafeString("".join([node.render_annotated(context) for node in self]))
  File "C:\Users\Crn96\Desktop\payglen\senv\lib\site-packages\django\template\base.py", line 1005, in <listcomp>
    return SafeString("".join([node.render_annotated(context) for node in self]))
  File "C:\Users\Crn96\Desktop\payglen\senv\lib\site-packages\django\template\base.py", line 966, in render_annotated
    return self.render(context)
  File "C:\Users\Crn96\Desktop\payglen\senv\lib\site-packages\django\template\loader_tags.py", line 63, in render
    result = block.nodelist.render(context)
  File "C:\Users\Crn96\Desktop\payglen\senv\lib\site-packages\django\template\base.py", line 1005, in render
    return SafeString("".join([node.render_annotated(context) for node in self]))
  File "C:\Users\Crn96\Desktop\payglen\senv\lib\site-packages\django\template\base.py", line 1005, in <listcomp>
    return SafeString("".join([node.render_annotated(context) for node in self]))
  File "C:\Users\Crn96\Desktop\payglen\senv\lib\site-packages\django\template\base.py", line 966, in render_annotated
    return self.render(context)
  File "C:\Users\Crn96\Desktop\payglen\senv\lib\site-packages\django\template\loader_tags.py", line 63, in render
    result = block.nodelist.render(context)
  File "C:\Users\Crn96\Desktop\payglen\senv\lib\site-packages\django\template\base.py", line 1005, in render
    return SafeString("".join([node.render_annotated(context) for node in self]))
  File "C:\Users\Crn96\Desktop\payglen\senv\lib\site-packages\django\template\base.py", line 1005, in <listcomp>
    return SafeString("".join([node.render_annotated(context) for node in self]))
  File "C:\Users\Crn96\Desktop\payglen\senv\lib\site-packages\django\template\base.py", line 966, in render_annotated
    return self.render(context)
  File "C:\Users\Crn96\Desktop\payglen\senv\lib\site-packages\django\template\loader_tags.py", line 63, in render
    result = block.nodelist.render(context)
  File "C:\Users\Crn96\Desktop\payglen\senv\lib\site-packages\django\template\base.py", line 1005, in render
    return SafeString("".join([node.render_annotated(context) for node in self]))
  File "C:\Users\Crn96\Desktop\payglen\senv\lib\site-packages\django\template\base.py", line 1005, in <listcomp>
    return SafeString("".join([node.render_annotated(context) for node in self]))
  File "C:\Users\Crn96\Desktop\payglen\senv\lib\site-packages\django\template\base.py", line 966, in render_annotated
    return self.render(context)
  File "C:\Users\Crn96\Desktop\payglen\senv\lib\site-packages\django\template\defaulttags.py", line 471, in render
    url = reverse(view_name, args=args, kwargs=kwargs, current_app=current_app)
  File "C:\Users\Crn96\Desktop\payglen\senv\lib\site-packages\django\urls\base.py", line 88, in reverse
    return resolver._reverse_with_prefix(view, prefix, *args, **kwargs)
  File "C:\Users\Crn96\Desktop\payglen\senv\lib\site-packages\django\urls\resolvers.py", line 828, in _reverse_with_prefix
    raise NoReverseMatch(msg)
django.urls.exceptions.NoReverseMatch: Reverse for 'currencies' not found. 'currencies' is not a valid view function or pattern name.
"GET /currencies/ HTTP/1.1" 500 423518
Internal Server Error: /accounthome
Traceback (most recent call last):
  File "C:\Users\Crn96\Desktop\payglen\senv\lib\site-packages\django\core\handlers\exception.py", line 55, in inner
    response = get_response(request)
  File "C:\Users\Crn96\Desktop\payglen\senv\lib\site-packages\django\core\handlers\base.py", line 197, in _get_response
    response = wrapped_callback(request, *callback_args, **callback_kwargs)
  File "C:\Users\Crn96\Desktop\payglen\myauth\views.py", line 99, in home
    return render(request, "basic/home.html", context)
  File "C:\Users\Crn96\Desktop\payglen\senv\lib\site-packages\django\shortcuts.py", line 24, in render
    content = loader.render_to_string(template_name, context, request, using=using)
  File "C:\Users\Crn96\Desktop\payglen\senv\lib\site-packages\django\template\loader.py", line 61, in render_to_string
    template = get_template(template_name, using=using)
  File "C:\Users\Crn96\Desktop\payglen\senv\lib\site-packages\django\template\loader.py", line 19, in get_template
    raise TemplateDoesNotExist(template_name, chain=chain)
django.template.exceptions.TemplateDoesNotExist: basic/home.html
"GET /accounthome HTTP/1.1" 500 88223
Internal Server Error: /currencies/
Traceback (most recent call last):
  File "C:\Users\Crn96\Desktop\payglen\senv\lib\site-packages\rest_framework\fields.py", line 446, in get_attribute
    return get_attribute(instance, self.source_attrs)
  File "C:\Users\Crn96\Desktop\payglen\senv\lib\site-packages\rest_framework\fields.py", line 96, in get_attribute
    instance = getattr(instance, attr)
AttributeError: 'Currency' object has no attribute 'USD'

During handling of the above exception, another exception occurred:

Traceback (most recent call last):
  File "C:\Users\Crn96\Desktop\payglen\senv\lib\site-packages\django\core\handlers\exception.py", line 55, in inner
    response = get_response(request)
  File "C:\Users\Crn96\Desktop\payglen\senv\lib\site-packages\django\core\handlers\base.py", line 197, in _get_response
    response = wrapped_callback(request, *callback_args, **callback_kwargs)
  File "C:\Users\Crn96\Desktop\payglen\senv\lib\site-packages\django\views\decorators\csrf.py", line 56, in wrapper_view
    return view_func(*args, **kwargs)
  File "C:\Users\Crn96\Desktop\payglen\senv\lib\site-packages\rest_framework\viewsets.py", line 125, in view
    return self.dispatch(request, *args, **kwargs)
  File "C:\Users\Crn96\Desktop\payglen\senv\lib\site-packages\rest_framework\views.py", line 509, in dispatch
    response = self.handle_exception(exc)
  File "C:\Users\Crn96\Desktop\payglen\senv\lib\site-packages\rest_framework\views.py", line 469, in handle_exception
    self.raise_uncaught_exception(exc)
  File "C:\Users\Crn96\Desktop\payglen\senv\lib\site-packages\rest_framework\views.py", line 480, in raise_uncaught_exception
    raise exc
  File "C:\Users\Crn96\Desktop\payglen\senv\lib\site-packages\rest_framework\views.py", line 506, in dispatch
    response = handler(request, *args, **kwargs)
  File "C:\Users\Crn96\Desktop\payglen\senv\lib\site-packages\rest_framework\mixins.py", line 43, in list
    return self.get_paginated_response(serializer.data)
  File "C:\Users\Crn96\Desktop\payglen\senv\lib\site-packages\rest_framework\serializers.py", line 768, in data
    ret = super().data
  File "C:\Users\Crn96\Desktop\payglen\senv\lib\site-packages\rest_framework\serializers.py", line 253, in data
    self._data = self.to_representation(self.instance)
  File "C:\Users\Crn96\Desktop\payglen\senv\lib\site-packages\rest_framework\serializers.py", line 686, in to_representation
    return [
  File "C:\Users\Crn96\Desktop\payglen\senv\lib\site-packages\rest_framework\serializers.py", line 687, in <listcomp>
    self.child.to_representation(item) for item in iterable
  File "C:\Users\Crn96\Desktop\payglen\senv\lib\site-packages\rest_framework\serializers.py", line 509, in to_representation
    attribute = field.get_attribute(instance)
  File "C:\Users\Crn96\Desktop\payglen\senv\lib\site-packages\rest_framework\fields.py", line 479, in get_attribute
    raise type(exc)(msg)
AttributeError: Got AttributeError when attempting to get a value for field `USD` on serializer `CurrencySerializer`.
The serializer field might be named incorrectly and not match any attribute or key on the `Currency` instance.
Original exception text was: 'Currency' object has no attribute 'USD'.
"GET /currencies/ HTTP/1.1" 500 155910
Internal Server Error: /currencies/
Traceback (most recent call last):
  File "C:\Users\Crn96\Desktop\payglen\senv\lib\site-packages\rest_framework\fields.py", line 446, in get_attribute
    return get_attribute(instance, self.source_attrs)
  File "C:\Users\Crn96\Desktop\payglen\senv\lib\site-packages\rest_framework\fields.py", line 96, in get_attribute
    instance = getattr(instance, attr)
AttributeError: 'Currency' object has no attribute 'USD'

During handling of the above exception, another exception occurred:

Traceback (most recent call last):
  File "C:\Users\Crn96\Desktop\payglen\senv\lib\site-packages\django\core\handlers\exception.py", line 55, in inner
    response = get_response(request)
  File "C:\Users\Crn96\Desktop\payglen\senv\lib\site-packages\django\core\handlers\base.py", line 197, in _get_response
    response = wrapped_callback(request, *callback_args, **callback_kwargs)
  File "C:\Users\Crn96\Desktop\payglen\senv\lib\site-packages\django\views\decorators\csrf.py", line 56, in wrapper_view
    return view_func(*args, **kwargs)
  File "C:\Users\Crn96\Desktop\payglen\senv\lib\site-packages\rest_framework\viewsets.py", line 125, in view
    return self.dispatch(request, *args, **kwargs)
  File "C:\Users\Crn96\Desktop\payglen\senv\lib\site-packages\rest_framework\views.py", line 509, in dispatch
    response = self.handle_exception(exc)
  File "C:\Users\Crn96\Desktop\payglen\senv\lib\site-packages\rest_framework\views.py", line 469, in handle_exception
    self.raise_uncaught_exception(exc)
  File "C:\Users\Crn96\Desktop\payglen\senv\lib\site-packages\rest_framework\views.py", line 480, in raise_uncaught_exception
    raise exc
  File "C:\Users\Crn96\Desktop\payglen\senv\lib\site-packages\rest_framework\views.py", line 506, in dispatch
    response = handler(request, *args, **kwargs)
  File "C:\Users\Crn96\Desktop\payglen\senv\lib\site-packages\rest_framework\mixins.py", line 43, in list
    return self.get_paginated_response(serializer.data)
  File "C:\Users\Crn96\Desktop\payglen\senv\lib\site-packages\rest_framework\serializers.py", line 768, in data
    ret = super().data
  File "C:\Users\Crn96\Desktop\payglen\senv\lib\site-packages\rest_framework\serializers.py", line 253, in data
    self._data = self.to_representation(self.instance)
  File "C:\Users\Crn96\Desktop\payglen\senv\lib\site-packages\rest_framework\serializers.py", line 686, in to_representation
    return [
  File "C:\Users\Crn96\Desktop\payglen\senv\lib\site-packages\rest_framework\serializers.py", line 687, in <listcomp>
    self.child.to_representation(item) for item in iterable
  File "C:\Users\Crn96\Desktop\payglen\senv\lib\site-packages\rest_framework\serializers.py", line 509, in to_representation
    attribute = field.get_attribute(instance)
  File "C:\Users\Crn96\Desktop\payglen\senv\lib\site-packages\rest_framework\fields.py", line 479, in get_attribute
    raise type(exc)(msg)
AttributeError: Got AttributeError when attempting to get a value for field `USD` on serializer `CurrencySerializer`.
The serializer field might be named incorrectly and not match any attribute or key on the `Currency` instance.
Original exception text was: 'Currency' object has no attribute 'USD'.
"GET /currencies/ HTTP/1.1" 500 155694
Internal Server Error: /currencies/
Traceback (most recent call last):
  File "C:\Users\Crn96\Desktop\payglen\senv\lib\site-packages\django\core\handlers\exception.py", line 55, in inner
    response = get_response(request)
  File "C:\Users\Crn96\Desktop\payglen\senv\lib\site-packages\django\core\handlers\base.py", line 197, in _get_response
    response = wrapped_callback(request, *callback_args, **callback_kwargs)
  File "C:\Users\Crn96\Desktop\payglen\senv\lib\site-packages\django\views\decorators\csrf.py", line 56, in wrapper_view
    return view_func(*args, **kwargs)
  File "C:\Users\Crn96\Desktop\payglen\senv\lib\site-packages\rest_framework\viewsets.py", line 125, in view
    return self.dispatch(request, *args, **kwargs)
  File "C:\Users\Crn96\Desktop\payglen\senv\lib\site-packages\rest_framework\views.py", line 509, in dispatch
    response = self.handle_exception(exc)
  File "C:\Users\Crn96\Desktop\payglen\senv\lib\site-packages\rest_framework\views.py", line 469, in handle_exception
    self.raise_uncaught_exception(exc)
  File "C:\Users\Crn96\Desktop\payglen\senv\lib\site-packages\rest_framework\views.py", line 480, in raise_uncaught_exception
    raise exc
  File "C:\Users\Crn96\Desktop\payglen\senv\lib\site-packages\rest_framework\views.py", line 506, in dispatch
    response = handler(request, *args, **kwargs)
  File "C:\Users\Crn96\Desktop\payglen\senv\lib\site-packages\rest_framework\mixins.py", line 43, in list
    return self.get_paginated_response(serializer.data)
  File "C:\Users\Crn96\Desktop\payglen\senv\lib\site-packages\rest_framework\serializers.py", line 768, in data
    ret = super().data
  File "C:\Users\Crn96\Desktop\payglen\senv\lib\site-packages\rest_framework\serializers.py", line 253, in data
    self._data = self.to_representation(self.instance)
  File "C:\Users\Crn96\Desktop\payglen\senv\lib\site-packages\rest_framework\serializers.py", line 686, in to_representation
    return [
  File "C:\Users\Crn96\Desktop\payglen\senv\lib\site-packages\rest_framework\serializers.py", line 687, in <listcomp>
    self.child.to_representation(item) for item in iterable
  File "C:\Users\Crn96\Desktop\payglen\senv\lib\site-packages\rest_framework\serializers.py", line 522, in to_representation
    ret[field.field_name] = field.to_representation(attribute)
  File "C:\Users\Crn96\Desktop\payglen\senv\lib\site-packages\rest_framework\fields.py", line 1081, in to_representation
    quantized = self.quantize(value)
  File "C:\Users\Crn96\Desktop\payglen\senv\lib\site-packages\rest_framework\fields.py", line 1100, in quantize
    return value.quantize(
decimal.InvalidOperation: [<class 'decimal.InvalidOperation'>]
"GET /currencies/?page=2 HTTP/1.1" 500 149592
Internal Server Error: /accounthome
Traceback (most recent call last):
  File "C:\Users\Crn96\Desktop\payglen\senv\lib\site-packages\django\core\handlers\exception.py", line 55, in inner
    response = get_response(request)
  File "C:\Users\Crn96\Desktop\payglen\senv\lib\site-packages\django\core\handlers\base.py", line 197, in _get_response
    response = wrapped_callback(request, *callback_args, **callback_kwargs)
  File "C:\Users\Crn96\Desktop\payglen\myauth\views.py", line 99, in home
    return render(request, "basic/home.html", context)
  File "C:\Users\Crn96\Desktop\payglen\senv\lib\site-packages\django\shortcuts.py", line 24, in render
    content = loader.render_to_string(template_name, context, request, using=using)
  File "C:\Users\Crn96\Desktop\payglen\senv\lib\site-packages\django\template\loader.py", line 61, in render_to_string
    template = get_template(template_name, using=using)
  File "C:\Users\Crn96\Desktop\payglen\senv\lib\site-packages\django\template\loader.py", line 19, in get_template
    raise TemplateDoesNotExist(template_name, chain=chain)
django.template.exceptions.TemplateDoesNotExist: basic/home.html
"GET /accounthome HTTP/1.1" 500 88230
Internal Server Error: /accountapi/apikeys/
Traceback (most recent call last):
  File "C:\Users\Crn96\Desktop\payglen\senv\lib\site-packages\django\db\backends\utils.py", line 89, in _execute
    return self.cursor.execute(sql, params)
  File "C:\Users\Crn96\Desktop\payglen\senv\lib\site-packages\django\db\backends\sqlite3\base.py", line 328, in execute
    return super().execute(query, params)
sqlite3.IntegrityError: NOT NULL constraint failed: myauth_apikey.user_id

The above exception was the direct cause of the following exception:

Traceback (most recent call last):
  File "C:\Users\Crn96\Desktop\payglen\senv\lib\site-packages\django\core\handlers\exception.py", line 55, in inner
    response = get_response(request)
  File "C:\Users\Crn96\Desktop\payglen\senv\lib\site-packages\django\core\handlers\base.py", line 197, in _get_response
    response = wrapped_callback(request, *callback_args, **callback_kwargs)
  File "C:\Users\Crn96\Desktop\payglen\senv\lib\site-packages\django\views\decorators\csrf.py", line 56, in wrapper_view
    return view_func(*args, **kwargs)
  File "C:\Users\Crn96\Desktop\payglen\senv\lib\site-packages\rest_framework\viewsets.py", line 125, in view
    return self.dispatch(request, *args, **kwargs)
  File "C:\Users\Crn96\Desktop\payglen\senv\lib\site-packages\rest_framework\views.py", line 509, in dispatch
    response = self.handle_exception(exc)
  File "C:\Users\Crn96\Desktop\payglen\senv\lib\site-packages\rest_framework\views.py", line 469, in handle_exception
    self.raise_uncaught_exception(exc)
  File "C:\Users\Crn96\Desktop\payglen\senv\lib\site-packages\rest_framework\views.py", line 480, in raise_uncaught_exception
    raise exc
  File "C:\Users\Crn96\Desktop\payglen\senv\lib\site-packages\rest_framework\views.py", line 506, in dispatch
    response = handler(request, *args, **kwargs)
  File "C:\Users\Crn96\Desktop\payglen\senv\lib\site-packages\rest_framework\mixins.py", line 19, in create
    self.perform_create(serializer)
  File "C:\Users\Crn96\Desktop\payglen\senv\lib\site-packages\rest_framework\mixins.py", line 24, in perform_create
    serializer.save()
  File "C:\Users\Crn96\Desktop\payglen\senv\lib\site-packages\rest_framework\serializers.py", line 212, in save
    self.instance = self.create(validated_data)
  File "C:\Users\Crn96\Desktop\payglen\senv\lib\site-packages\rest_framework\serializers.py", line 962, in create
    instance = ModelClass._default_manager.create(**validated_data)
  File "C:\Users\Crn96\Desktop\payglen\senv\lib\site-packages\django\db\models\manager.py", line 87, in manager_method
    return getattr(self.get_queryset(), name)(*args, **kwargs)
  File "C:\Users\Crn96\Desktop\payglen\senv\lib\site-packages\django\db\models\query.py", line 658, in create
    obj.save(force_insert=True, using=self.db)
  File "C:\Users\Crn96\Desktop\payglen\senv\lib\site-packages\django\db\models\base.py", line 814, in save
    self.save_base(
  File "C:\Users\Crn96\Desktop\payglen\senv\lib\site-packages\django\db\models\base.py", line 877, in save_base
    updated = self._save_table(
  File "C:\Users\Crn96\Desktop\payglen\senv\lib\site-packages\django\db\models\base.py", line 1020, in _save_table
    results = self._do_insert(
  File "C:\Users\Crn96\Desktop\payglen\senv\lib\site-packages\django\db\models\base.py", line 1061, in _do_insert
    return manager._insert(
  File "C:\Users\Crn96\Desktop\payglen\senv\lib\site-packages\django\db\models\manager.py", line 87, in manager_method
    return getattr(self.get_queryset(), name)(*args, **kwargs)
  File "C:\Users\Crn96\Desktop\payglen\senv\lib\site-packages\django\db\models\query.py", line 1805, in _insert
    return query.get_compiler(using=using).execute_sql(returning_fields)
  File "C:\Users\Crn96\Desktop\payglen\senv\lib\site-packages\django\db\models\sql\compiler.py", line 1822, in execute_sql
    cursor.execute(sql, params)
  File "C:\Users\Crn96\Desktop\payglen\senv\lib\site-packages\django\db\backends\utils.py", line 102, in execute
    return super().execute(sql, params)
  File "C:\Users\Crn96\Desktop\payglen\senv\lib\site-packages\django\db\backends\utils.py", line 67, in execute
    return self._execute_with_wrappers(
  File "C:\Users\Crn96\Desktop\payglen\senv\lib\site-packages\django\db\backends\utils.py", line 80, in _execute_with_wrappers
    return executor(sql, params, many, context)
  File "C:\Users\Crn96\Desktop\payglen\senv\lib\site-packages\django\db\backends\utils.py", line 89, in _execute
    return self.cursor.execute(sql, params)
  File "C:\Users\Crn96\Desktop\payglen\senv\lib\site-packages\django\db\utils.py", line 91, in __exit__
    raise dj_exc_value.with_traceback(traceback) from exc_value
  File "C:\Users\Crn96\Desktop\payglen\senv\lib\site-packages\django\db\backends\utils.py", line 89, in _execute
    return self.cursor.execute(sql, params)
  File "C:\Users\Crn96\Desktop\payglen\senv\lib\site-packages\django\db\backends\sqlite3\base.py", line 328, in execute
    return super().execute(query, params)
django.db.utils.IntegrityError: NOT NULL constraint failed: myauth_apikey.user_id
"POST /accountapi/apikeys/ HTTP/1.1" 500 26048
Internal Server Error: /account/users
Traceback (most recent call last):
  File "C:\Users\Crn96\Desktop\payglen\senv\lib\site-packages\django\core\handlers\exception.py", line 55, in inner
    response = get_response(request)
  File "C:\Users\Crn96\Desktop\payglen\senv\lib\site-packages\django\utils\deprecation.py", line 136, in __call__
    response = self.process_response(request, response)
  File "C:\Users\Crn96\Desktop\payglen\senv\lib\site-packages\django\middleware\common.py", line 108, in process_response
    return self.response_redirect_class(self.get_full_path_with_slash(request))
  File "C:\Users\Crn96\Desktop\payglen\senv\lib\site-packages\django\middleware\common.py", line 87, in get_full_path_with_slash
    raise RuntimeError(
RuntimeError: You called this URL via POST, but the URL doesn't end in a slash and you have APPEND_SLASH set. Django can't redirect to the slash URL while maintaining POST data. Change your form to point to 127.0.0.1:8000/account/users/ (note the trailing slash), or set APPEND_SLASH=False in your Django settings.
"POST /account/users HTTP/1.1" 500 75741
Internal Server Error: /account/users
Traceback (most recent call last):
  File "C:\Users\Crn96\Desktop\payglen\senv\lib\site-packages\django\core\handlers\exception.py", line 55, in inner
    response = get_response(request)
  File "C:\Users\Crn96\Desktop\payglen\senv\lib\site-packages\django\utils\deprecation.py", line 136, in __call__
    response = self.process_response(request, response)
  File "C:\Users\Crn96\Desktop\payglen\senv\lib\site-packages\django\middleware\common.py", line 108, in process_response
    return self.response_redirect_class(self.get_full_path_with_slash(request))
  File "C:\Users\Crn96\Desktop\payglen\senv\lib\site-packages\django\middleware\common.py", line 87, in get_full_path_with_slash
    raise RuntimeError(
RuntimeError: You called this URL via POST, but the URL doesn't end in a slash and you have APPEND_SLASH set. Django can't redirect to the slash URL while maintaining POST data. Change your form to point to 127.0.0.1:8000/account/users/ (note the trailing slash), or set APPEND_SLASH=False in your Django settings.
"POST /account/users HTTP/1.1" 500 75740
Internal Server Error: /users
Traceback (most recent call last):
  File "C:\Users\Crn96\Desktop\payglen\senv\lib\site-packages\django\core\handlers\exception.py", line 55, in inner
    response = get_response(request)
  File "C:\Users\Crn96\Desktop\payglen\senv\lib\site-packages\django\utils\deprecation.py", line 136, in __call__
    response = self.process_response(request, response)
  File "C:\Users\Crn96\Desktop\payglen\senv\lib\site-packages\django\middleware\common.py", line 108, in process_response
    return self.response_redirect_class(self.get_full_path_with_slash(request))
  File "C:\Users\Crn96\Desktop\payglen\senv\lib\site-packages\django\middleware\common.py", line 87, in get_full_path_with_slash
    raise RuntimeError(
RuntimeError: You called this URL via POST, but the URL doesn't end in a slash and you have APPEND_SLASH set. Django can't redirect to the slash URL while maintaining POST data. Change your form to point to 127.0.0.1:8000/users/ (note the trailing slash), or set APPEND_SLASH=False in your Django settings.
"POST /users HTTP/1.1" 500 75607
Internal Server Error: /forex/currencies
Traceback (most recent call last):
  File "C:\Users\Crn96\Desktop\payglen\senv\lib\site-packages\django\core\handlers\exception.py", line 55, in inner
    response = get_response(request)
  File "C:\Users\Crn96\Desktop\payglen\senv\lib\site-packages\django\utils\deprecation.py", line 136, in __call__
    response = self.process_response(request, response)
  File "C:\Users\Crn96\Desktop\payglen\senv\lib\site-packages\django\middleware\common.py", line 108, in process_response
    return self.response_redirect_class(self.get_full_path_with_slash(request))
  File "C:\Users\Crn96\Desktop\payglen\senv\lib\site-packages\django\middleware\common.py", line 87, in get_full_path_with_slash
    raise RuntimeError(
RuntimeError: You called this URL via POST, but the URL doesn't end in a slash and you have APPEND_SLASH set. Django can't redirect to the slash URL while maintaining POST data. Change your form to point to 127.0.0.1:8000/forex/currencies/?auth_token=c35b801075f6c6dc11cd94cd8fbc7ba8a12c1b0f (note the trailing slash), or set APPEND_SLASH=False in your Django settings.
"POST /forex/currencies?auth_token=c35b801075f6c6dc11cd94cd8fbc7ba8a12c1b0f HTTP/1.1" 500 76568
Internal Server Error: /accounts/profile/
Traceback (most recent call last):
  File "C:\Users\Crn96\Desktop\payglen\senv\lib\site-packages\django\core\handlers\exception.py", line 55, in inner
    response = get_response(request)
  File "C:\Users\Crn96\Desktop\payglen\senv\lib\site-packages\django\core\handlers\base.py", line 197, in _get_response
    response = wrapped_callback(request, *callback_args, **callback_kwargs)
  File "C:\Users\Crn96\Desktop\payglen\senv\lib\site-packages\django\contrib\auth\decorators.py", line 23, in _wrapper_view
    return view_func(request, *args, **kwargs)
  File "C:\Users\Crn96\Desktop\payglen\myauth\views.py", line 376, in profile
    return render(request,"auth/profile.html",context)
  File "C:\Users\Crn96\Desktop\payglen\senv\lib\site-packages\django\shortcuts.py", line 24, in render
    content = loader.render_to_string(template_name, context, request, using=using)
  File "C:\Users\Crn96\Desktop\payglen\senv\lib\site-packages\django\template\loader.py", line 61, in render_to_string
    template = get_template(template_name, using=using)
  File "C:\Users\Crn96\Desktop\payglen\senv\lib\site-packages\django\template\loader.py", line 19, in get_template
    raise TemplateDoesNotExist(template_name, chain=chain)
django.template.exceptions.TemplateDoesNotExist: auth/profile.html
"GET /accounts/profile/ HTTP/1.1" 500 94823
Internal Server Error: /accounts/login
Traceback (most recent call last):
  File "C:\Users\Crn96\Desktop\payglen\senv\lib\site-packages\django\core\handlers\exception.py", line 55, in inner
    response = get_response(request)
  File "C:\Users\Crn96\Desktop\payglen\senv\lib\site-packages\django\utils\deprecation.py", line 136, in __call__
    response = self.process_response(request, response)
  File "C:\Users\Crn96\Desktop\payglen\senv\lib\site-packages\django\middleware\common.py", line 108, in process_response
    return self.response_redirect_class(self.get_full_path_with_slash(request))
  File "C:\Users\Crn96\Desktop\payglen\senv\lib\site-packages\django\middleware\common.py", line 87, in get_full_path_with_slash
    raise RuntimeError(
RuntimeError: You called this URL via POST, but the URL doesn't end in a slash and you have APPEND_SLASH set. Django can't redirect to the slash URL while maintaining POST data. Change your form to point to 127.0.0.1:8000/accounts/login/ (note the trailing slash), or set APPEND_SLASH=False in your Django settings.
"POST /accounts/login HTTP/1.1" 500 75853
Internal Server Error: /accounts/login
Traceback (most recent call last):
  File "C:\Users\Crn96\Desktop\payglen\senv\lib\site-packages\django\core\handlers\exception.py", line 55, in inner
    response = get_response(request)
  File "C:\Users\Crn96\Desktop\payglen\senv\lib\site-packages\django\utils\deprecation.py", line 136, in __call__
    response = self.process_response(request, response)
  File "C:\Users\Crn96\Desktop\payglen\senv\lib\site-packages\django\middleware\common.py", line 108, in process_response
    return self.response_redirect_class(self.get_full_path_with_slash(request))
  File "C:\Users\Crn96\Desktop\payglen\senv\lib\site-packages\django\middleware\common.py", line 87, in get_full_path_with_slash
    raise RuntimeError(
RuntimeError: You called this URL via POST, but the URL doesn't end in a slash and you have APPEND_SLASH set. Django can't redirect to the slash URL while maintaining POST data. Change your form to point to 127.0.0.1:8000/accounts/login/ (note the trailing slash), or set APPEND_SLASH=False in your Django settings.
"POST /accounts/login HTTP/1.1" 500 75853
Internal Server Error: /admin/login/
Traceback (most recent call last):
  File "C:\Users\Crn96\Desktop\payglen\senv\lib\site-packages\django\db\backends\utils.py", line 89, in _execute
    return self.cursor.execute(sql, params)
  File "C:\Users\Crn96\Desktop\payglen\senv\lib\site-packages\django\db\backends\sqlite3\base.py", line 328, in execute
    return super().execute(query, params)
sqlite3.OperationalError: no such column: myauth_newuser.api_key

The above exception was the direct cause of the following exception:

Traceback (most recent call last):
  File "C:\Users\Crn96\Desktop\payglen\senv\lib\site-packages\django\core\handlers\exception.py", line 55, in inner
    response = get_response(request)
  File "C:\Users\Crn96\Desktop\payglen\senv\lib\site-packages\django\core\handlers\base.py", line 197, in _get_response
    response = wrapped_callback(request, *callback_args, **callback_kwargs)
  File "C:\Users\Crn96\Desktop\payglen\senv\lib\site-packages\django\utils\decorators.py", line 46, in _wrapper
    return bound_method(*args, **kwargs)
  File "C:\Users\Crn96\Desktop\payglen\senv\lib\site-packages\django\views\decorators\cache.py", line 62, in _wrapper_view_func
    response = view_func(request, *args, **kwargs)
  File "C:\Users\Crn96\Desktop\payglen\senv\lib\site-packages\django\contrib\admin\sites.py", line 441, in login
    return LoginView.as_view(**defaults)(request)
  File "C:\Users\Crn96\Desktop\payglen\senv\lib\site-packages\django\views\generic\base.py", line 104, in view
    return self.dispatch(request, *args, **kwargs)
  File "C:\Users\Crn96\Desktop\payglen\senv\lib\site-packages\django\utils\decorators.py", line 46, in _wrapper
    return bound_method(*args, **kwargs)
  File "C:\Users\Crn96\Desktop\payglen\senv\lib\site-packages\django\views\decorators\debug.py", line 92, in sensitive_post_parameters_wrapper
    return view(request, *args, **kwargs)
  File "C:\Users\Crn96\Desktop\payglen\senv\lib\site-packages\django\utils\decorators.py", line 46, in _wrapper
    return bound_method(*args, **kwargs)
  File "C:\Users\Crn96\Desktop\payglen\senv\lib\site-packages\django\utils\decorators.py", line 134, in _wrapper_view
    response = view_func(request, *args, **kwargs)
  File "C:\Users\Crn96\Desktop\payglen\senv\lib\site-packages\django\utils\decorators.py", line 46, in _wrapper
    return bound_method(*args, **kwargs)
  File "C:\Users\Crn96\Desktop\payglen\senv\lib\site-packages\django\views\decorators\cache.py", line 62, in _wrapper_view_func
    response = view_func(request, *args, **kwargs)
  File "C:\Users\Crn96\Desktop\payglen\senv\lib\site-packages\django\contrib\auth\views.py", line 90, in dispatch
    return super().dispatch(request, *args, **kwargs)
  File "C:\Users\Crn96\Desktop\payglen\senv\lib\site-packages\django\views\generic\base.py", line 143, in dispatch
    return handler(request, *args, **kwargs)
  File "C:\Users\Crn96\Desktop\payglen\senv\lib\site-packages\django\views\generic\edit.py", line 152, in post
    if form.is_valid():
  File "C:\Users\Crn96\Desktop\payglen\senv\lib\site-packages\django\forms\forms.py", line 201, in is_valid
    return self.is_bound and not self.errors
  File "C:\Users\Crn96\Desktop\payglen\senv\lib\site-packages\django\forms\forms.py", line 196, in errors
    self.full_clean()
  File "C:\Users\Crn96\Desktop\payglen\senv\lib\site-packages\django\forms\forms.py", line 434, in full_clean
    self._clean_form()
  File "C:\Users\Crn96\Desktop\payglen\senv\lib\site-packages\django\forms\forms.py", line 455, in _clean_form
    cleaned_data = self.clean()
  File "C:\Users\Crn96\Desktop\payglen\senv\lib\site-packages\django\contrib\auth\forms.py", line 242, in clean
    self.user_cache = authenticate(
  File "C:\Users\Crn96\Desktop\payglen\senv\lib\site-packages\django\views\decorators\debug.py", line 42, in sensitive_variables_wrapper
    return func(*func_args, **func_kwargs)
  File "C:\Users\Crn96\Desktop\payglen\senv\lib\site-packages\django\contrib\auth\__init__.py", line 77, in authenticate
    user = backend.authenticate(request, **credentials)
  File "C:\Users\Crn96\Desktop\payglen\senv\lib\site-packages\django\contrib\auth\backends.py", line 46, in authenticate
    user = UserModel._default_manager.get_by_natural_key(username)
  File "C:\Users\Crn96\Desktop\payglen\senv\lib\site-packages\django\contrib\auth\base_user.py", line 54, in get_by_natural_key
    return self.get(**{self.model.USERNAME_FIELD: username})
  File "C:\Users\Crn96\Desktop\payglen\senv\lib\site-packages\django\db\models\manager.py", line 87, in manager_method
    return getattr(self.get_queryset(), name)(*args, **kwargs)
  File "C:\Users\Crn96\Desktop\payglen\senv\lib\site-packages\django\db\models\query.py", line 633, in get
    num = len(clone)
  File "C:\Users\Crn96\Desktop\payglen\senv\lib\site-packages\django\db\models\query.py", line 380, in __len__
    self._fetch_all()
  File "C:\Users\Crn96\Desktop\payglen\senv\lib\site-packages\django\db\models\query.py", line 1881, in _fetch_all
    self._result_cache = list(self._iterable_class(self))
  File "C:\Users\Crn96\Desktop\payglen\senv\lib\site-packages\django\db\models\query.py", line 91, in __iter__
    results = compiler.execute_sql(
  File "C:\Users\Crn96\Desktop\payglen\senv\lib\site-packages\django\db\models\sql\compiler.py", line 1562, in execute_sql
    cursor.execute(sql, params)
  File "C:\Users\Crn96\Desktop\payglen\senv\lib\site-packages\django\db\backends\utils.py", line 102, in execute
    return super().execute(sql, params)
  File "C:\Users\Crn96\Desktop\payglen\senv\lib\site-packages\django\db\backends\utils.py", line 67, in execute
    return self._execute_with_wrappers(
  File "C:\Users\Crn96\Desktop\payglen\senv\lib\site-packages\django\db\backends\utils.py", line 80, in _execute_with_wrappers
    return executor(sql, params, many, context)
  File "C:\Users\Crn96\Desktop\payglen\senv\lib\site-packages\django\db\backends\utils.py", line 89, in _execute
    return self.cursor.execute(sql, params)
  File "C:\Users\Crn96\Desktop\payglen\senv\lib\site-packages\django\db\utils.py", line 91, in __exit__
    raise dj_exc_value.with_traceback(traceback) from exc_value
  File "C:\Users\Crn96\Desktop\payglen\senv\lib\site-packages\django\db\backends\utils.py", line 89, in _execute
    return self.cursor.execute(sql, params)
  File "C:\Users\Crn96\Desktop\payglen\senv\lib\site-packages\django\db\backends\sqlite3\base.py", line 328, in execute
    return super().execute(query, params)
django.db.utils.OperationalError: no such column: myauth_newuser.api_key
"POST /admin/login/?next=/admin/ HTTP/1.1" 500 245941
